Workbook

Sheet Assumptions
A1: Assumptions
A2: Cells in Orange are assumptions | M2: MONTHLY | BV2: YEARLY
A3: Year | M3: 1 | N3: 1 | O3: 1 | P3: 1 | Q3: 1 | R3: 1 | S3: 1 | T3: 1 | U3: 1 | V3: 1 | W3: 1 | X3: 1 | Y3: =X3+1 -> 2 | Z3: =Y3 -> 2 | AA3: =Z3 -> 2 | AB3: =AA3 -> 2 | AC3: =AB3 -> 2 | AD3: =AC3 -> 2 | AE3: =AD3 -> 2 | AF3: =AE3 -> 2 | AG3: =AF3 -> 2 | ... AJ3: =AI3 -> 2 | AK3: 3 | AL3: 3 | AM3: 3 | AN3: 3 | AO3: 3 | AP3: 3 | AQ3: 3 | AR3: 3 | AS3: 3 | AT3: 3 | AU3: 3 | AV3: 3 | AW3: 4 | AX3: 4 | AY3: 4 | AZ3: 4 | BA3: 4 | BB3: 4 | BC3: 4 | BD3: 4 | BE3: 4 | BF3: 4 | BG3: 4 | BH3: 4 | BI3: 5 | BJ3: 5 | BK3: 5 | BL3: 5 | BM3: 5 | BN3: 5 | BO3: 5 | BP3: 5 | BQ3: 5 | BR3: 5 | BS3: 5 | BT3: 5 | BV3: 1 | BW3: 2 | BX3: 3 | BY3: 4 | BZ3: 5
A4: Months | M4: 1 | N4: =M4+1 -> 2 | O4: =N4+1 -> 3 | P4: =O4+1 -> 4 | Q4: =P4+1 -> 5 | R4: =Q4+1 -> 6 | S4: =R4+1 -> 7 | T4: =S4+1 -> 8 | U4: =T4+1 -> 9 | ... BT4: =BS4+1 -> 60 | BV4: 12 | BW4: 24 | BX4: 36 | BY4: 48 | BZ4: 60
A5: Revenue Assumptions
A6: Converation Rate | G6: 0.05 | H6: =G6 -> 0.05 | M6: =G6 -> 0.05 | N6: =M6+($H6-$G6)/COUNT($N$4:$BT$4) -> 0.05 | O6: =N6+($H6-$G6)/COUNT($N$4:$BT$4) -> 0.05 | P6: =O6+($H6-$G6)/COUNT($N$4:$BT$4) -> 0.05 | Q6: =P6+($H6-$G6)/COUNT($N$4:$BT$4) -> 0.05 | R6: =Q6+($H6-$G6)/COUNT($N$4:$BT$4) -> 0.05 | S6: =R6+($H6-$G6)/COUNT($N$4:$BT$4) -> 0.05 | T6: =S6+($H6-$G6)/COUNT($N$4:$BT$4) -> 0.05 | U6: =T6+($H6-$G6)/COUNT($N$4:$BT$4) -> 0.05 | ... BT6: =BS6+($H6-$G6)/COUNT($N$4:$BT$4) -> 0.05
A7: Type 1 SMBs Annual Cost | F7: INR | G7: =10000*12 -> 120000 | H7: =G7 -> 120000 | M7: =G7 -> 120000 | N7: =M7+($H7-$G7)/COUNT($N$4:$BT$4) -> 120000 | O7: =N7+($H7-$G7)/COUNT($N$4:$BT$4) -> 120000 | P7: =O7+($H7-$G7)/COUNT($N$4:$BT$4) -> 120000 | Q7: =P7+($H7-$G7)/COUNT($N$4:$BT$4) -> 120000 | R7: =Q7+($H7-$G7)/COUNT($N$4:$BT$4) -> 120000 | S7: =R7+($H7-$G7)/COUNT($N$4:$BT$4) -> 120000 | T7: =S7+($H7-$G7)/COUNT($N$4:$BT$4) -> 120000 | U7: =T7+($H7-$G7)/COUNT($N$4:$BT$4) -> 120000 | ... BT7: =BS7+($H7-$G7)/COUNT($N$4:$BT$4) -> 120000
A8: Type 2 SMBs Annual Cost | F8: INR | G8: =5000*12 -> 60000 | H8: =G8 -> 60000 | M8: =G8 -> 60000 | N8: =M8+($H8-$G8)/COUNT($N$4:$BT$4) -> 60000 | O8: =N8+($H8-$G8)/COUNT($N$4:$BT$4) -> 60000 | P8: =O8+($H8-$G8)/COUNT($N$4:$BT$4) -> 60000 | Q8: =P8+($H8-$G8)/COUNT($N$4:$BT$4) -> 60000 | R8: =Q8+($H8-$G8)/COUNT($N$4:$BT$4) -> 60000 | S8: =R8+($H8-$G8)/COUNT($N$4:$BT$4) -> 60000 | T8: =S8+($H8-$G8)/COUNT($N$4:$BT$4) -> 60000 | U8: =T8+($H8-$G8)/COUNT($N$4:$BT$4) -> 60000 | ... BT8: =BS8+($H8-$G8)/COUNT($N$4:$BT$4) -> 60000
A9: Duration of Contract | F9: Months | G9: 12 | H9: =G9 -> 12 | M9: =G9 -> 12 | N9: =M9+($H9-$G9)/COUNT($N$4:$BT$4) -> 12 | O9: =N9+($H9-$G9)/COUNT($N$4:$BT$4) -> 12 | P9: =O9+($H9-$G9)/COUNT($N$4:$BT$4) -> 12 | Q9: =P9+($H9-$G9)/COUNT($N$4:$BT$4) -> 12 | R9: =Q9+($H9-$G9)/COUNT($N$4:$BT$4) -> 12 | S9: =R9+($H9-$G9)/COUNT($N$4:$BT$4) -> 12 | T9: =S9+($H9-$G9)/COUNT($N$4:$BT$4) -> 12 | U9: =T9+($H9-$G9)/COUNT($N$4:$BT$4) -> 12 | ... BT9: =BS9+($H9-$G9)/COUNT($N$4:$BT$4) -> 12
A10: Churn & Expansion Revenue
A11: Annual Churn Rate | F11: % | G11: 0.3 | H11: =G11 -> 0.3 | M11: =G11 -> 0.3 | N11: =M11+($H11-$G11)/COUNT($N$4:$BT$4) -> 0.3 | O11: =N11+($H11-$G11)/COUNT($N$4:$BT$4) -> 0.3 | P11: =O11+($H11-$G11)/COUNT($N$4:$BT$4) -> 0.3 | Q11: =P11+($H11-$G11)/COUNT($N$4:$BT$4) -> 0.3 | R11: =Q11+($H11-$G11)/COUNT($N$4:$BT$4) -> 0.3 | S11: =R11+($H11-$G11)/COUNT($N$4:$BT$4) -> 0.3 | T11: =S11+($H11-$G11)/COUNT($N$4:$BT$4) -> 0.3 | U11: =T11+($H11-$G11)/COUNT($N$4:$BT$4) -> 0.3 | ... BT11: =BS11+($H11-$G11)/COUNT($N$4:$BT$4) -> 0.3
A12: Recurring Contracts | F12: % | G12: =1-G11 -> 0.7 | H12: =1-H11 -> 0.7 | M12: =G12 -> 0.7 | N12: =M12+($H12-$G12)/COUNT($N$4:$BT$4) -> 0.7 | O12: =N12+($H12-$G12)/COUNT($N$4:$BT$4) -> 0.7 | P12: =O12+($H12-$G12)/COUNT($N$4:$BT$4) -> 0.7 | Q12: =P12+($H12-$G12)/COUNT($N$4:$BT$4) -> 0.7 | R12: =Q12+($H12-$G12)/COUNT($N$4:$BT$4) -> 0.7 | S12: =R12+($H12-$G12)/COUNT($N$4:$BT$4) -> 0.7 | T12: =S12+($H12-$G12)/COUNT($N$4:$BT$4) -> 0.7 | U12: =T12+($H12-$G12)/COUNT($N$4:$BT$4) -> 0.7 | ... BT12: =BS12+($H12-$G12)/COUNT($N$4:$BT$4) -> 0.7
A13: % Exapansion Added | F13: % | G13: 0.2 | H13: =G13 -> 0.2 | M13: =G13 -> 0.2 | N13: =M13+($H13-$G13)/COUNT($N$4:$BT$4) -> 0.2 | O13: =N13+($H13-$G13)/COUNT($N$4:$BT$4) -> 0.2 | P13: =O13+($H13-$G13)/COUNT($N$4:$BT$4) -> 0.2 | Q13: =P13+($H13-$G13)/COUNT($N$4:$BT$4) -> 0.2 | R13: =Q13+($H13-$G13)/COUNT($N$4:$BT$4) -> 0.2 | S13: =R13+($H13-$G13)/COUNT($N$4:$BT$4) -> 0.2 | T13: =S13+($H13-$G13)/COUNT($N$4:$BT$4) -> 0.2 | U13: =T13+($H13-$G13)/COUNT($N$4:$BT$4) -> 0.2 | ... BT13: =BS13+($H13-$G13)/COUNT($N$4:$BT$4) -> 0.2
A14: Cost Assumptions
A15: Direct Cost
A16: Hosting & Infrastructure Costs
A17: Cloud services (AWS, Google Cloud, Azure) | F17: Monthly Cost | G17: 50000 | H17: =G17*10 -> 500000 | M17: =G17 -> 50000 | N17: =M17+($H17-$G17)/COUNT($N$4:$BT$4) -> 57627.119 | O17: =N17+($H17-$G17)/COUNT($N$4:$BT$4) -> 65254.237 | P17: =O17+($H17-$G17)/COUNT($N$4:$BT$4) -> 72881.356 | Q17: =P17+($H17-$G17)/COUNT($N$4:$BT$4) -> 80508.475 | R17: =Q17+($H17-$G17)/COUNT($N$4:$BT$4) -> 88135.593 | S17: =R17+($H17-$G17)/COUNT($N$4:$BT$4) -> 95762.712 | T17: =S17+($H17-$G17)/COUNT($N$4:$BT$4) -> 103389.83 | U17: =T17+($H17-$G17)/COUNT($N$4:$BT$4) -> 111016.95 | ... BT17: =BS17+($H17-$G17)/COUNT($N$4:$BT$4) -> 500000 | BV17: =SUMIF($M$3:$BT$3,BV$3,$M17:$BT17) -> 1103389.8 | BW17: =SUMIF($M$3:$BT$3,BW$3,$M17:$BT17) -> 2201694.9 | BX17: =SUMIF($M$3:$BT$3,BX$3,$M17:$BT17) -> 3300000 | BY17: =SUMIF($M$3:$BT$3,BY$3,$M17:$BT17) -> 4398305.1 | BZ17: =SUMIF($M$3:$BT$3,BZ$3,$M17:$BT17) -> 5496610.2
A18: Database and storage (Amazon RDS, MongoDB Atlas) | F18: Monthly Cost | G18: 10000 | H18: =G18*10 -> 100000 | M18: =G18 -> 10000 | N18: =M18+($H18-$G18)/COUNT($N$4:$BT$4) -> 11525.424 | O18: =N18+($H18-$G18)/COUNT($N$4:$BT$4) -> 13050.847 | P18: =O18+($H18-$G18)/COUNT($N$4:$BT$4) -> 14576.271 | Q18: =P18+($H18-$G18)/COUNT($N$4:$BT$4) -> 16101.695 | R18: =Q18+($H18-$G18)/COUNT($N$4:$BT$4) -> 17627.119 | S18: =R18+($H18-$G18)/COUNT($N$4:$BT$4) -> 19152.542 | T18: =S18+($H18-$G18)/COUNT($N$4:$BT$4) -> 20677.966 | U18: =T18+($H18-$G18)/COUNT($N$4:$BT$4) -> 22203.39 | ... BT18: =BS18+($H18-$G18)/COUNT($N$4:$BT$4) -> 100000 | BV18: =SUMIF($M$3:$BT$3,BV$3,$M18:$BT18) -> 220677.97 | BW18: =SUMIF($M$3:$BT$3,BW$3,$M18:$BT18) -> 440338.98 | BX18: =SUMIF($M$3:$BT$3,BX$3,$M18:$BT18) -> 660000 | BY18: =SUMIF($M$3:$BT$3,BY$3,$M18:$BT18) -> 879661.02 | BZ18: =SUMIF($M$3:$BT$3,BZ$3,$M18:$BT18) -> 1099322
A19: Content delivery networks (CDN) | F19: Monthly Cost | G19: =30*86 -> 2580 | H19: =G19*5 -> 12900 | M19: =G19 -> 2580 | N19: =M19+($H19-$G19)/COUNT($N$4:$BT$4) -> 2754.9153 | O19: =N19+($H19-$G19)/COUNT($N$4:$BT$4) -> 2929.8305 | P19: =O19+($H19-$G19)/COUNT($N$4:$BT$4) -> 3104.7458 | Q19: =P19+($H19-$G19)/COUNT($N$4:$BT$4) -> 3279.661 | R19: =Q19+($H19-$G19)/COUNT($N$4:$BT$4) -> 3454.5763 | S19: =R19+($H19-$G19)/COUNT($N$4:$BT$4) -> 3629.4915 | T19: =S19+($H19-$G19)/COUNT($N$4:$BT$4) -> 3804.4068 | U19: =T19+($H19-$G19)/COUNT($N$4:$BT$4) -> 3979.322 | ... BT19: =BS19+($H19-$G19)/COUNT($N$4:$BT$4) -> 12900 | BV19: =SUMIF($M$3:$BT$3,BV$3,$M19:$BT19) -> 42504.407 | BW19: =SUMIF($M$3:$BT$3,BW$3,$M19:$BT19) -> 67692.203 | BX19: =SUMIF($M$3:$BT$3,BX$3,$M19:$BT19) -> 92880 | BY19: =SUMIF($M$3:$BT$3,BY$3,$M19:$BT19) -> 118067.8 | BZ19: =SUMIF($M$3:$BT$3,BZ$3,$M19:$BT19) -> 143255.59
A20: Third-Party Software & API Costs
A21: Payment gateway fees (e.g., Stripe, Razorpay) | F21: as a % of bookings | G21: 0.015 | H21: =G21 -> 0.015 | M21: =G21 -> 0.015 | N21: =M21+($H21-$G21)/COUNT($N$4:$BT$4) -> 0.015 | O21: =N21+($H21-$G21)/COUNT($N$4:$BT$4) -> 0.015 | P21: =O21+($H21-$G21)/COUNT($N$4:$BT$4) -> 0.015 | Q21: =P21+($H21-$G21)/COUNT($N$4:$BT$4) -> 0.015 | R21: =Q21+($H21-$G21)/COUNT($N$4:$BT$4) -> 0.015 | S21: =R21+($H21-$G21)/COUNT($N$4:$BT$4) -> 0.015 | T21: =S21+($H21-$G21)/COUNT($N$4:$BT$4) -> 0.015 | U21: =T21+($H21-$G21)/COUNT($N$4:$BT$4) -> 0.015 | ... BT21: =BS21+($H21-$G21)/COUNT($N$4:$BT$4) -> 0.015
A22: Security services (e.g., Cloudflare, Auth0) | F22: Monthly Cost | G22: 5000 | H22: =G22*5 -> 25000 | M22: =G22 -> 5000 | N22: =M22+($H22-$G22)/COUNT($N$4:$BT$4) -> 5338.9831 | O22: =N22+($H22-$G22)/COUNT($N$4:$BT$4) -> 5677.9661 | P22: =O22+($H22-$G22)/COUNT($N$4:$BT$4) -> 6016.9492 | Q22: =P22+($H22-$G22)/COUNT($N$4:$BT$4) -> 6355.9322 | R22: =Q22+($H22-$G22)/COUNT($N$4:$BT$4) -> 6694.9153 | S22: =R22+($H22-$G22)/COUNT($N$4:$BT$4) -> 7033.8983 | T22: =S22+($H22-$G22)/COUNT($N$4:$BT$4) -> 7372.8814 | U22: =T22+($H22-$G22)/COUNT($N$4:$BT$4) -> 7711.8644 | ... BT22: =BS22+($H22-$G22)/COUNT($N$4:$BT$4) -> 25000 | BV22: =SUMIF($M$3:$BT$3,BV$3,$M22:$BT22) -> 82372.881 | BW22: =SUMIF($M$3:$BT$3,BW$3,$M22:$BT22) -> 131186.44 | BX22: =SUMIF($M$3:$BT$3,BX$3,$M22:$BT22) -> 180000 | BY22: =SUMIF($M$3:$BT$3,BY$3,$M22:$BT22) -> 228813.56 | BZ22: =SUMIF($M$3:$BT$3,BZ$3,$M22:$BT22) -> 277627.12
A23: Headcount | BW23: ]
A24: Customer Support | F24: Account/Customer support | G24: 40 | H24: 40 | M24: =G24 -> 40 | N24: =M24+($H24-$G24)/COUNT($N$4:$BT$4) -> 40 | O24: =N24+($H24-$G24)/COUNT($N$4:$BT$4) -> 40 | P24: =O24+($H24-$G24)/COUNT($N$4:$BT$4) -> 40 | Q24: =P24+($H24-$G24)/COUNT($N$4:$BT$4) -> 40 | R24: =Q24+($H24-$G24)/COUNT($N$4:$BT$4) -> 40 | S24: =R24+($H24-$G24)/COUNT($N$4:$BT$4) -> 40 | T24: =S24+($H24-$G24)/COUNT($N$4:$BT$4) -> 40 | U24: =T24+($H24-$G24)/COUNT($N$4:$BT$4) -> 40 | ... BT24: =BS24+($H24-$G24)/COUNT($N$4:$BT$4) -> 40
A25: Customer Support | F25: Monthly Salary/Headcount | G25: 40000 | H25: 0.15 | I25: Annual Increment
A26: Operating Expense
A27: Sales & Marketing Expense
A28: Sales Funnel
A29: Advetising/Marketing Expense Type 1 SMBs Focused | M29: 150000 | N29: =M29 -> 150000 | O29: =N29 -> 150000 | P29: =O29+100000 -> 250000 | Q29: =P29 -> 250000 | R29: =Q29 -> 250000 | S29: =R29*2 -> 500000 | T29: =S29 -> 500000 | U29: =T29 -> 500000 | V29: =U29+250000 -> 750000 | W29: =V29 -> 750000 | X29: =W29 -> 750000 | Y29: =X29+100000 -> 850000 | Z29: =Y29 -> 850000 | AA29: =Z29 -> 850000 | AB29: =AA29+150000 -> 1000000 | AC29: =AB29 -> 1000000 | AD29: =AC29 -> 1000000 | AE29: =AD29*2 -> 2000000 | AF29: =AE29 -> 2000000 | AG29: =AF29 -> 2000000 | AH29: =AG29+200000 -> 2200000 | AI29: =AH29 -> 2200000 | AJ29: =AI29 -> 2200000 | AK29: =AJ29+100000 -> 2300000 | AL29: =AK29 -> 2300000 | AM29: =AL29 -> 2300000 | AN29: =AM29+100000 -> 2400000 | AO29: =AN29 -> 2400000 | AP29: =AO29 -> 2400000 | AQ29: =AP29+100000 -> 2500000 | AR29: =AQ29 -> 2500000 | AS29: =AR29 -> 2500000 | AT29: =AS29+100000 -> 2600000 | AU29: =AT29 -> 2600000 | AV29: =AU29 -> 2600000 | AW29: =AV29+400000 -> 3000000 | AX29: =AW29 -> 3000000 | AY29: =AX29 -> 3000000 | AZ29: =AY29+100000 -> 3100000 | BA29: =AZ29 -> 3100000 | BB29: =BA29 -> 3100000 | BC29: =BB29+100000 -> 3200000 | BD29: =BC29 -> 3200000 | BE29: =BD29 -> 3200000 | BF29: =BE29+100000 -> 3300000 | BG29: =BF29 -> 3300000 | BH29: =BG29 -> 3300000 | BI29: =BH29+400000 -> 3700000 | BJ29: =BI29 -> 3700000 | BK29: =BJ29 -> 3700000 | BL29: =BK29+100000 -> 3800000 | BM29: =BL29 -> 3800000 | BN29: =BM29 -> 3800000 | BO29: =BN29+100000 -> 3900000 | BP29: =BO29 -> 3900000 | BQ29: =BP29 -> 3900000 | BR29: =BQ29+100000 -> 4000000 | BS29: =BR29 -> 4000000 | BT29: =BS29 -> 4000000 | BV29: =SUMIF($M$3:$BT$3,BV$3,$M29:$BT29) -> 4950000 | BW29: =SUMIF($M$3:$BT$3,BW$3,$M29:$BT29) -> 18150000 | BX29: =SUMIF($M$3:$BT$3,BX$3,$M29:$BT29) -> 29400000 | BY29: =SUMIF($M$3:$BT$3,BY$3,$M29:$BT29) -> 37800000 | BZ29: =SUMIF($M$3:$BT$3,BZ$3,$M29:$BT29) -> 46200000
A30: Advetising/Marketing Expense Type 2 SMBs Focused | M30: 75000 | N30: 75000 | O30: 75000 | P30: 125000 | Q30: 125000 | R30: 125000 | S30: 250000 | T30: 250000 | U30: 250000 | V30: 375000 | W30: 375000 | X30: 375000 | Y30: 425000 | Z30: 425000 | AA30: 425000 | AB30: 500000 | AC30: 500000 | AD30: 500000 | AE30: 1000000 | AF30: 1000000 | AG30: 1000000 | AH30: 1100000 | AI30: 1100000 | AJ30: 1100000 | AK30: 1150000 | AL30: 1150000 | AM30: 1150000 | AN30: 1200000 | AO30: 1200000 | AP30: 1200000 | AQ30: 1250000 | AR30: 1250000 | AS30: 1250000 | AT30: 1300000 | AU30: 1300000 | AV30: 1300000 | AW30: =AV30+1300000 -> 2600000 | AX30: =AW30 -> 2600000 | AY30: =AX30 -> 2600000 | AZ30: =AY30+200000 -> 2800000 | BA30: =AZ30 -> 2800000 | BB30: =BA30 -> 2800000 | BC30: =BB30+200000 -> 3000000 | BD30: =BC30 -> 3000000 | BE30: =BD30 -> 3000000 | BF30: =BE30+200000 -> 3200000 | BG30: =BF30 -> 3200000 | BH30: =BG30 -> 3200000 | BI30: =BH30+800000 -> 4000000 | BJ30: =BI30 -> 4000000 | BK30: =BJ30 -> 4000000 | BL30: =BK30+100000 -> 4100000 | BM30: =BL30 -> 4100000 | BN30: =BM30 -> 4100000 | BO30: =BN30+100000 -> 4200000 | BP30: =BO30 -> 4200000 | BQ30: =BP30 -> 4200000 | BR30: =BQ30+100000 -> 4300000 | BS30: =BR30 -> 4300000 | BT30: =BS30 -> 4300000
A31: Cost/Lead Type 1 | G31: 2000 | H31: =G31 -> 2000 | M31: =G31 -> 2000 | N31: =M31+($H31-$G31)/COUNT($N$4:$BT$4) -> 2000 | O31: =N31+($H31-$G31)/COUNT($N$4:$BT$4) -> 2000 | P31: =O31+($H31-$G31)/COUNT($N$4:$BT$4) -> 2000 | Q31: =P31+($H31-$G31)/COUNT($N$4:$BT$4) -> 2000 | R31: =Q31+($H31-$G31)/COUNT($N$4:$BT$4) -> 2000 | S31: =R31+($H31-$G31)/COUNT($N$4:$BT$4) -> 2000 | T31: =S31+($H31-$G31)/COUNT($N$4:$BT$4) -> 2000 | U31: =T31+($H31-$G31)/COUNT($N$4:$BT$4) -> 2000 | ... BT31: =BS31+($H31-$G31)/COUNT($N$4:$BT$4) -> 2000
A32: Cost/Lead Type 2 | G32: 1000 | H32: =G32 -> 1000 | M32: =G32 -> 1000 | N32: =M32+($H32-$G32)/COUNT($N$4:$BT$4) -> 1000 | O32: =N32+($H32-$G32)/COUNT($N$4:$BT$4) -> 1000 | P32: =O32+($H32-$G32)/COUNT($N$4:$BT$4) -> 1000 | Q32: =P32+($H32-$G32)/COUNT($N$4:$BT$4) -> 1000 | R32: =Q32+($H32-$G32)/COUNT($N$4:$BT$4) -> 1000 | S32: =R32+($H32-$G32)/COUNT($N$4:$BT$4) -> 1000 | T32: =S32+($H32-$G32)/COUNT($N$4:$BT$4) -> 1000 | U32: =T32+($H32-$G32)/COUNT($N$4:$BT$4) -> 1000 | ... BT32: =BS32+($H32-$G32)/COUNT($N$4:$BT$4) -> 1000
A33: Sales Commission %
A34: New Bookings | F34: as a % repective bookings | G34: 0.1 | H34: =G34 -> 0.1 | M34: =G34 -> 0.1 | N34: =M34+($H34-$G34)/COUNT($N$4:$BT$4) -> 0.1 | O34: =N34+($H34-$G34)/COUNT($N$4:$BT$4) -> 0.1 | P34: =O34+($H34-$G34)/COUNT($N$4:$BT$4) -> 0.1 | Q34: =P34+($H34-$G34)/COUNT($N$4:$BT$4) -> 0.1 | R34: =Q34+($H34-$G34)/COUNT($N$4:$BT$4) -> 0.1 | S34: =R34+($H34-$G34)/COUNT($N$4:$BT$4) -> 0.1 | T34: =S34+($H34-$G34)/COUNT($N$4:$BT$4) -> 0.1 | U34: =T34+($H34-$G34)/COUNT($N$4:$BT$4) -> 0.1 | ... BT34: =BS34+($H34-$G34)/COUNT($N$4:$BT$4) -> 0.1
A35: Renewals | F35: as a % repective bookings | G35: 0.025 | H35: =G35 -> 0.025 | M35: =G35 -> 0.025 | N35: =M35+($H35-$G35)/COUNT($N$4:$BT$4) -> 0.025 | O35: =N35+($H35-$G35)/COUNT($N$4:$BT$4) -> 0.025 | P35: =O35+($H35-$G35)/COUNT($N$4:$BT$4) -> 0.025 | Q35: =P35+($H35-$G35)/COUNT($N$4:$BT$4) -> 0.025 | R35: =Q35+($H35-$G35)/COUNT($N$4:$BT$4) -> 0.025 | S35: =R35+($H35-$G35)/COUNT($N$4:$BT$4) -> 0.025 | T35: =S35+($H35-$G35)/COUNT($N$4:$BT$4) -> 0.025 | U35: =T35+($H35-$G35)/COUNT($N$4:$BT$4) -> 0.025 | ... BT35: =BS35+($H35-$G35)/COUNT($N$4:$BT$4) -> 0.025
A36: Expansion | F36: as a % repective bookings | G36: 0.05 | H36: =G36 -> 0.05 | M36: =G36 -> 0.05 | N36: =M36+($H36-$G36)/COUNT($N$4:$BT$4) -> 0.05 | O36: =N36+($H36-$G36)/COUNT($N$4:$BT$4) -> 0.05 | P36: =O36+($H36-$G36)/COUNT($N$4:$BT$4) -> 0.05 | Q36: =P36+($H36-$G36)/COUNT($N$4:$BT$4) -> 0.05 | R36: =Q36+($H36-$G36)/COUNT($N$4:$BT$4) -> 0.05 | S36: =R36+($H36-$G36)/COUNT($N$4:$BT$4) -> 0.05 | T36: =S36+($H36-$G36)/COUNT($N$4:$BT$4) -> 0.05 | U36: =T36+($H36-$G36)/COUNT($N$4:$BT$4) -> 0.05 | ... BT36: =BS36+($H36-$G36)/COUNT($N$4:$BT$4) -> 0.05
A37: Headcount
A38: Sales (SDR) | F38: Leads/Sales Agent/Month | G38: 50 | H38: =G38 -> 50 | M38: =G38 -> 50 | N38: =M38+($H38-$G38)/COUNT($N$4:$BT$4) -> 50 | O38: =N38+($H38-$G38)/COUNT($N$4:$BT$4) -> 50 | P38: =O38+($H38-$G38)/COUNT($N$4:$BT$4) -> 50 | Q38: =P38+($H38-$G38)/COUNT($N$4:$BT$4) -> 50 | R38: =Q38+($H38-$G38)/COUNT($N$4:$BT$4) -> 50 | S38: =R38+($H38-$G38)/COUNT($N$4:$BT$4) -> 50 | T38: =S38+($H38-$G38)/COUNT($N$4:$BT$4) -> 50 | U38: =T38+($H38-$G38)/COUNT($N$4:$BT$4) -> 50 | ... BT38: =BS38+($H38-$G38)/COUNT($N$4:$BT$4) -> 50
A39: Sales Manager | F39: Sales Agents/Sales Manager | G39: 10 | H39: =G39 -> 10 | M39: =G39 -> 10 | N39: =M39+($H39-$G39)/COUNT($N$4:$BT$4) -> 10 | O39: =N39+($H39-$G39)/COUNT($N$4:$BT$4) -> 10 | P39: =O39+($H39-$G39)/COUNT($N$4:$BT$4) -> 10 | Q39: =P39+($H39-$G39)/COUNT($N$4:$BT$4) -> 10 | R39: =Q39+($H39-$G39)/COUNT($N$4:$BT$4) -> 10 | S39: =R39+($H39-$G39)/COUNT($N$4:$BT$4) -> 10 | T39: =S39+($H39-$G39)/COUNT($N$4:$BT$4) -> 10 | U39: =T39+($H39-$G39)/COUNT($N$4:$BT$4) -> 10 | ... BT39: =BS39+($H39-$G39)/COUNT($N$4:$BT$4) -> 10
A40: Sales Team Salary
...

Sheet Revenue Buildup
A1: Revenue Buildup
A2: Cells in Orange are assumptions | M2: MONTHLY | BV2: YEARLY
A3: Year | M3: 1 | N3: 1 | O3: 1 | P3: 1 | Q3: 1 | R3: 1 | S3: 1 | T3: 1 | U3: 1 | V3: 1 | W3: 1 | X3: 1 | Y3: =X3+1 -> 2 | Z3: =Y3 -> 2 | AA3: =Z3 -> 2 | AB3: =AA3 -> 2 | AC3: =AB3 -> 2 | AD3: =AC3 -> 2 | AE3: =AD3 -> 2 | AF3: =AE3 -> 2 | AG3: =AF3 -> 2 | ... AJ3: =AI3 -> 2 | AK3: 3 | AL3: 3 | AM3: 3 | AN3: 3 | AO3: 3 | AP3: 3 | AQ3: 3 | AR3: 3 | AS3: 3 | AT3: 3 | AU3: 3 | AV3: 3 | AW3: 4 | AX3: 4 | AY3: 4 | AZ3: 4 | BA3: 4 | BB3: 4 | BC3: 4 | BD3: 4 | BE3: 4 | BF3: 4 | BG3: 4 | BH3: 4 | BI3: 5 | BJ3: 5 | BK3: 5 | BL3: 5 | BM3: 5 | BN3: 5 | BO3: 5 | BP3: 5 | BQ3: 5 | BR3: 5 | BS3: 5 | BT3: 5 | BV3: 1 | BW3: 2 | BX3: 3 | BY3: 4 | BZ3: 5
A4: Months | M4: 1 | N4: =M4+1 -> 2 | O4: =N4+1 -> 3 | P4: =O4+1 -> 4 | Q4: =P4+1 -> 5 | R4: =Q4+1 -> 6 | S4: =R4+1 -> 7 | T4: =S4+1 -> 8 | U4: =T4+1 -> 9 | ... BT4: =BS4+1 -> 60 | BV4: 12 | BW4: 24 | BX4: 36 | BY4: 48 | BZ4: 60
A5: Type 1 SMB's
A6: Active Customers
A7: New Clients | M7: =ROUND('Cost Buildup'!M26*Assumptions!M6,0) -> 4 | N7: =ROUND('Cost Buildup'!N26*Assumptions!N6,0) -> 4 | O7: =ROUND('Cost Buildup'!O26*Assumptions!O6,0) -> 4 | P7: =ROUND('Cost Buildup'!P26*Assumptions!P6,0) -> 6 | Q7: =ROUND('Cost Buildup'!Q26*Assumptions!Q6,0) -> 6 | R7: =ROUND('Cost Buildup'!R26*Assumptions!R6,0) -> 6 | S7: =ROUND('Cost Buildup'!S26*Assumptions!S6,0) -> 13 | T7: =ROUND('Cost Buildup'!T26*Assumptions!T6,0) -> 13 | ... BT7: =ROUND('Cost Buildup'!BT26*Assumptions!BT6,0) -> 100 | BV7: =SUMIF($M$3:$BT$3,BV$3,$M7:$BT7) -> 126 | BW7: =SUMIF($M$3:$BT$3,BW$3,$M7:$BT7) -> 453 | BX7: =SUMIF($M$3:$BT$3,BX$3,$M7:$BT7) -> 738 | BY7: =SUMIF($M$3:$BT$3,BY$3,$M7:$BT7) -> 948 | BZ7: =SUMIF($M$3:$BT$3,BZ$3,$M7:$BT7) -> 1158
A8: Existing Clients | M8: 41 | N8: =M10 -> 45 | O8: =N10 -> 49 | P8: =O10 -> 53 | Q8: =P10 -> 59 | R8: =Q10 -> 65 | S8: =R10 -> 71 | T8: =S10 -> 84 | U8: =T10 -> 97 | ... BT8: =BS10 -> 2705 | BV8: =M8 -> 41 | BW8: =BV10 -> 167 | BX8: =BW10 -> 581 | BY8: =BX10 -> 1181 | BZ8: =BY10 -> 1907
A9: Churned | Y9: =-ROUND(M7*Assumptions!Y11,0) -> -1 | Z9: =-ROUND(N7*Assumptions!Z11,0) -> -1 | AA9: =-ROUND(O7*Assumptions!AA11,0) -> -1 | AB9: =-ROUND(P7*Assumptions!AB11,0) -> -2 | AC9: =-ROUND(Q7*Assumptions!AC11,0) -> -2 | AD9: =-ROUND(R7*Assumptions!AD11,0) -> -2 | AE9: =-ROUND(S7*Assumptions!AE11,0) -> -4 | AF9: =-ROUND(T7*Assumptions!AF11,0) -> -4 | ... BT9: =-ROUND(BH7*Assumptions!BT11,0) -> -25 | BV9: =SUMIF($M$3:$BT$3,BV$3,$M9:$BT9) -> 0 | BW9: =SUMIF($M$3:$BT$3,BW$3,$M9:$BT9) -> -39 | BX9: =SUMIF($M$3:$BT$3,BX$3,$M9:$BT9) -> -138 | BY9: =SUMIF($M$3:$BT$3,BY$3,$M9:$BT9) -> -222 | BZ9: =SUMIF($M$3:$BT$3,BZ$3,$M9:$BT9) -> -285
A10: Total Clinets | M10: =SUM(M7:M9) -> 45 | N10: =SUM(N7:N9) -> 49 | O10: =SUM(O7:O9) -> 53 | P10: =SUM(P7:P9) -> 59 | Q10: =SUM(Q7:Q9) -> 65 | R10: =SUM(R7:R9) -> 71 | S10: =SUM(S7:S9) -> 84 | T10: =SUM(T7:T9) -> 97 | ... BT10: =SUM(BT7:BT9) -> 2780 | BV10: =SUM(BV7:BV9) -> 167 | BW10: =SUM(BW7:BW9) -> 581 | BX10: =SUM(BX7:BX9) -> 1181 | BY10: =SUM(BY7:BY9) -> 1907 | BZ10: =SUM(BZ7:BZ9) -> 2780
A11: Bookings
A12: New Bookings | M12: =M7*Assumptions!M7 -> 480000 | N12: =N7*Assumptions!N7 -> 480000 | O12: =O7*Assumptions!O7 -> 480000 | P12: =P7*Assumptions!P7 -> 720000 | Q12: =Q7*Assumptions!Q7 -> 720000 | R12: =R7*Assumptions!R7 -> 720000 | S12: =S7*Assumptions!S7 -> 1560000 | T12: =T7*Assumptions!T7 -> 1560000 | ... BT12: =BT7*Assumptions!BT7 -> 12000000 | BV12: =SUMIF($M$3:$BT$3,BV$3,$M12:$BT12) -> 15120000 | BW12: =SUMIF($M$3:$BT$3,BW$3,$M12:$BT12) -> 54360000 | BX12: =SUMIF($M$3:$BT$3,BX$3,$M12:$BT12) -> 88560000 | BY12: =SUMIF($M$3:$BT$3,BY$3,$M12:$BT12) -> 113760000 | BZ12: =SUMIF($M$3:$BT$3,BZ$3,$M12:$BT12) -> 138960000
A13: Recurring Bookings
A14: Renewal | Y14: =(M7+Y9)*Assumptions!Y7 -> 360000 | Z14: =(N7+Z9)*Assumptions!Z7 -> 360000 | AA14: =(O7+AA9)*Assumptions!AA7 -> 360000 | AB14: =(P7+AB9)*Assumptions!AB7 -> 480000 | AC14: =(Q7+AC9)*Assumptions!AC7 -> 480000 | AD14: =(R7+AD9)*Assumptions!AD7 -> 480000 | AE14: =(S7+AE9)*Assumptions!AE7 -> 1080000 | AF14: =(T7+AF9)*Assumptions!AF7 -> 1080000 | ... BT14: =(BH7+BT9)*Assumptions!BT7 -> 6960000 | BV14: =SUMIF($M$3:$BT$3,BV$3,$M14:$BT14) -> 0 | BW14: =SUMIF($M$3:$BT$3,BW$3,$M14:$BT14) -> 10440000 | BX14: =SUMIF($M$3:$BT$3,BX$3,$M14:$BT14) -> 37800000 | BY14: =SUMIF($M$3:$BT$3,BY$3,$M14:$BT14) -> 61920000 | BZ14: =SUMIF($M$3:$BT$3,BZ$3,$M14:$BT14) -> 79560000
A15: Expansion | Y15: =Y14*Assumptions!Y13 -> 72000 | Z15: =Z14*Assumptions!Z13 -> 72000 | AA15: =AA14*Assumptions!AA13 -> 72000 | AB15: =AB14*Assumptions!AB13 -> 96000 | AC15: =AC14*Assumptions!AC13 -> 96000 | AD15: =AD14*Assumptions!AD13 -> 96000 | AE15: =AE14*Assumptions!AE13 -> 216000 | AF15: =AF14*Assumptions!AF13 -> 216000 | ... BT15: =BT14*Assumptions!BT13 -> 1392000 | BV15: =SUMIF($M$3:$BT$3,BV$3,$M15:$BT15) -> 0 | BW15: =SUMIF($M$3:$BT$3,BW$3,$M15:$BT15) -> 2088000 | BX15: =SUMIF($M$3:$BT$3,BX$3,$M15:$BT15) -> 7560000 | BY15: =SUMIF($M$3:$BT$3,BY$3,$M15:$BT15) -> 12384000 | BZ15: =SUMIF($M$3:$BT$3,BZ$3,$M15:$BT15) -> 15912000
A16: Total Recurring Bookings | M16: =SUM(M14:M15) -> 0 | N16: =SUM(N14:N15) -> 0 | O16: =SUM(O14:O15) -> 0 | P16: =SUM(P14:P15) -> 0 | Q16: =SUM(Q14:Q15) -> 0 | R16: =SUM(R14:R15) -> 0 | S16: =SUM(S14:S15) -> 0 | T16: =SUM(T14:T15) -> 0 | ... BT16: =SUM(BT14:BT15) -> 8352000 | BV16: =SUMIF($M$3:$BT$3,BV$3,$M16:$BT16) -> 0 | BW16: =SUMIF($M$3:$BT$3,BW$3,$M16:$BT16) -> 12528000 | BX16: =SUMIF($M$3:$BT$3,BX$3,$M16:$BT16) -> 45360000 | BY16: =SUMIF($M$3:$BT$3,BY$3,$M16:$BT16) -> 74304000 | BZ16: =SUMIF($M$3:$BT$3,BZ$3,$M16:$BT16) -> 95472000
A18: Total Bookings | M18: =M12+M16 -> 480000 | N18: =N12+N16 -> 480000 | O18: =O12+O16 -> 480000 | P18: =P12+P16 -> 720000 | Q18: =Q12+Q16 -> 720000 | R18: =R12+R16 -> 720000 | S18: =S12+S16 -> 1560000 | T18: =T12+T16 -> 1560000 | ... BT18: =BT12+BT16 -> 20352000 | BV18: =SUMIF($M$3:$BT$3,BV$3,$M18:$BT18) -> 15120000 | BW18: =SUMIF($M$3:$BT$3,BW$3,$M18:$BT18) -> 66888000 | BX18: =SUMIF($M$3:$BT$3,BX$3,$M18:$BT18) -> 133920000 | BY18: =SUMIF($M$3:$BT$3,BY$3,$M18:$BT18) -> 188064000 | BZ18: =SUMIF($M$3:$BT$3,BZ$3,$M18:$BT18) -> 234432000
A19: Revenue
A20: Revenue (MRR) | M20: =SUM('Revenue Buildup'!$M$18:M18)/Assumptions!M9 -> 40000 | N20: =SUM('Revenue Buildup'!$M$18:N18)/Assumptions!N9 -> 80000 | O20: =SUM('Revenue Buildup'!$M$18:O18)/Assumptions!O9 -> 120000 | P20: =SUM('Revenue Buildup'!$M$18:P18)/Assumptions!P9 -> 180000 | Q20: =SUM('Revenue Buildup'!$M$18:Q18)/Assumptions!Q9 -> 240000 | R20: =SUM('Revenue Buildup'!$M$18:R18)/Assumptions!R9 -> 300000 | S20: =SUM('Revenue Buildup'!$M$18:S18)/Assumptions!S9 -> 430000 | T20: =SUM('Revenue Buildup'!$M$18:T18)/Assumptions!T9 -> 560000 | ... W20: =SUM('Revenue Buildup'!$M$18:W18)/Assumptions!W9 -> 1070000 | X20: =SUM('Revenue Buildup'!M18:X18)/Assumptions!X9 -> 1260000 | Y20: =SUM('Revenue Buildup'!N18:Y18)/Assumptions!Y9 -> 1466000 | Z20: =SUM('Revenue Buildup'!O18:Z18)/Assumptions!Z9 -> 1672000 | AA20: =SUM('Revenue Buildup'!P18:AA18)/Assumptions!AA9 -> 1878000 | AB20: =SUM('Revenue Buildup'!Q18:AB18)/Assumptions!AB9 -> 2116000 | AC20: =SUM('Revenue Buildup'!R18:AC18)/Assumptions!AC9 -> 2354000 | AD20: =SUM('Revenue Buildup'!S18:AD18)/Assumptions!AD9 -> 2592000 | AE20: =SUM('Revenue Buildup'!T18:AE18)/Assumptions!AE9 -> 3070000 | ... BT20: =SUM('Revenue Buildup'!BI18:BT18)/Assumptions!BT9 -> 19536000 | BV20: =SUMIF($M$3:$BT$3,BV$3,$M20:$BT20) -> 5850000 | BW20: =SUMIF($M$3:$BT$3,BW$3,$M20:$BT20) -> 37896000 | BX20: =SUMIF($M$3:$BT$3,BX$3,$M20:$BT20) -> 105024000 | BY20: =SUMIF($M$3:$BT$3,BY$3,$M20:$BT20) -> 167100000 | BZ20: =SUMIF($M$3:$BT$3,BZ$3,$M20:$BT20) -> 213000000
A21: ARR | M21: =M20*12 -> 480000 | N21: =N20*12 -> 960000 | O21: =O20*12 -> 1440000 | P21: =P20*12 -> 2160000 | Q21: =Q20*12 -> 2880000 | R21: =R20*12 -> 3600000 | S21: =S20*12 -> 5160000 | T21: =T20*12 -> 6720000 | ... BT21: =BT20*12 -> 234432000
A22: Type 2 SMB's
A23: Active Customers
A24: New Clients | M24: =ROUND('Cost Buildup'!M27*Assumptions!M6,0) -> 4 | N24: =ROUND('Cost Buildup'!N27*Assumptions!N6,0) -> 4 | O24: =ROUND('Cost Buildup'!O27*Assumptions!O6,0) -> 4 | P24: =ROUND('Cost Buildup'!P27*Assumptions!P6,0) -> 6 | Q24: =ROUND('Cost Buildup'!Q27*Assumptions!Q6,0) -> 6 | R24: =ROUND('Cost Buildup'!R27*Assumptions!R6,0) -> 6 | S24: =ROUND('Cost Buildup'!S27*Assumptions!S6,0) -> 13 | T24: =ROUND('Cost Buildup'!T27*Assumptions!T6,0) -> 13 | ... BT24: =ROUND('Cost Buildup'!BT27*Assumptions!BT6,0) -> 215 | BV24: =SUMIF($M$3:$BT$3,BV$3,$M24:$BT24) -> 126 | BW24: =SUMIF($M$3:$BT$3,BW$3,$M24:$BT24) -> 453 | BX24: =SUMIF($M$3:$BT$3,BX$3,$M24:$BT24) -> 738 | BY24: =SUMIF($M$3:$BT$3,BY$3,$M24:$BT24) -> 1740 | BZ24: =SUMIF($M$3:$BT$3,BZ$3,$M24:$BT24) -> 2490
A25: Existing Clients | M25: 0 | N25: =M27 -> 4 | O25: =N27 -> 8 | P25: =O27 -> 12 | Q25: =P27 -> 18 | R25: =Q27 -> 24 | S25: =R27 -> 30 | T25: =S27 -> 43 | U25: =T27 -> 56 | ... BT25: =BS27 -> 5332 | BV25: =M25 -> 0 | BW25: =BV27 -> 126 | BX25: =BW27 -> 579 | BY25: =BX27 -> 1317 | BZ25: =BY27 -> 3057
A26: Churned | Y26: =-ROUND(M24*Assumptions!Y28,0) -> 0 | Z26: =-ROUND(N24*Assumptions!Z28,0) -> 0 | AA26: =-ROUND(O24*Assumptions!AA28,0) -> 0 | AB26: =-ROUND(P24*Assumptions!AB28,0) -> 0 | AC26: =-ROUND(Q24*Assumptions!AC28,0) -> 0 | AD26: =-ROUND(R24*Assumptions!AD28,0) -> 0 | AE26: =-ROUND(S24*Assumptions!AE28,0) -> 0 | AF26: =-ROUND(T24*Assumptions!AF28,0) -> 0 | ... BT26: =-ROUND(BH24*Assumptions!BT28,0) -> 0 | BV26: =SUMIF($M$3:$BT$3,BV$3,$M26:$BT26) -> 0 | BW26: =SUMIF($M$3:$BT$3,BW$3,$M26:$BT26) -> 0 | BX26: =SUMIF($M$3:$BT$3,BX$3,$M26:$BT26) -> 0 | BY26: =SUMIF($M$3:$BT$3,BY$3,$M26:$BT26) -> 0 | BZ26: =SUMIF($M$3:$BT$3,BZ$3,$M26:$BT26) -> 0
A27: Total Clinets | M27: =SUM(M24:M26) -> 4 | N27: =SUM(N24:N26) -> 8 | O27: =SUM(O24:O26) -> 12 | P27: =SUM(P24:P26) -> 18 | Q27: =SUM(Q24:Q26) -> 24 | R27: =SUM(R24:R26) -> 30 | S27: =SUM(S24:S26) -> 43 | T27: =SUM(T24:T26) -> 56 | ... BT27: =SUM(BT24:BT26) -> 5547 | BV27: =SUM(BV24:BV26) -> 126 | BW27: =SUM(BW24:BW26) -> 579 | BX27: =SUM(BX24:BX26) -> 1317 | BY27: =SUM(BY24:BY26) -> 3057 | BZ27: =SUM(BZ24:BZ26) -> 5547
A28: Bookings
A29: New Bookings | M29: =M24*Assumptions!M8 -> 240000 | N29: =N24*Assumptions!N8 -> 240000 | O29: =O24*Assumptions!O8 -> 240000 | P29: =P24*Assumptions!P8 -> 360000 | Q29: =Q24*Assumptions!Q8 -> 360000 | R29: =R24*Assumptions!R8 -> 360000 | S29: =S24*Assumptions!S8 -> 780000 | T29: =T24*Assumptions!T8 -> 780000 | ... BT29: =BT24*Assumptions!BT8 -> 12900000 | BV29: =SUMIF($M$3:$BT$3,BV$3,$M29:$BT29) -> 7560000 | BW29: =SUMIF($M$3:$BT$3,BW$3,$M29:$BT29) -> 27180000 | BX29: =SUMIF($M$3:$BT$3,BX$3,$M29:$BT29) -> 44280000 | BY29: =SUMIF($M$3:$BT$3,BY$3,$M29:$BT29) -> 104400000 | BZ29: =SUMIF($M$3:$BT$3,BZ$3,$M29:$BT29) -> 149400000
A30: Recurring Bookings
A31: Renewal | Y31: =(M24+Y26)*Assumptions!Y8 -> 240000 | Z31: =(N24+Z26)*Assumptions!Z8 -> 240000 | AA31: =(O24+AA26)*Assumptions!AA8 -> 240000 | AB31: =(P24+AB26)*Assumptions!AB8 -> 360000 | AC31: =(Q24+AC26)*Assumptions!AC8 -> 360000 | AD31: =(R24+AD26)*Assumptions!AD8 -> 360000 | AE31: =(S24+AE26)*Assumptions!AE8 -> 780000 | AF31: =(T24+AF26)*Assumptions!AF8 -> 780000 | ... BT31: =(BH24+BT26)*Assumptions!BT8 -> 9600000 | BV31: =SUMIF($M$3:$BT$3,BV$3,$M31:$BT31) -> 0 | BW31: =SUMIF($M$3:$BT$3,BW$3,$M31:$BT31) -> 7560000 | BX31: =SUMIF($M$3:$BT$3,BX$3,$M31:$BT31) -> 27180000 | BY31: =SUMIF($M$3:$BT$3,BY$3,$M31:$BT31) -> 44280000 | BZ31: =SUMIF($M$3:$BT$3,BZ$3,$M31:$BT31) -> 104400000
A32: Expansion | Y32: =Y31*Assumptions!Y13 -> 48000 | Z32: =Z31*Assumptions!Z13 -> 48000 | AA32: =AA31*Assumptions!AA13 -> 48000 | AB32: =AB31*Assumptions!AB13 -> 72000 | AC32: =AC31*Assumptions!AC13 -> 72000 | AD32: =AD31*Assumptions!AD13 -> 72000 | AE32: =AE31*Assumptions!AE13 -> 156000 | AF32: =AF31*Assumptions!AF13 -> 156000 | ... BT32: =BT31*Assumptions!BT13 -> 1920000 | BV32: =SUMIF($M$3:$BT$3,BV$3,$M32:$BT32) -> 0 | BW32: =SUMIF($M$3:$BT$3,BW$3,$M32:$BT32) -> 1512000 | BX32: =SUMIF($M$3:$BT$3,BX$3,$M32:$BT32) -> 5436000 | BY32: =SUMIF($M$3:$BT$3,BY$3,$M32:$BT32) -> 8856000 | BZ32: =SUMIF($M$3:$BT$3,BZ$3,$M32:$BT32) -> 20880000
A33: Total Recurring Bookings | M33: =SUM(M31:M32) -> 0 | N33: =SUM(N31:N32) -> 0 | O33: =SUM(O31:O32) -> 0 | P33: =SUM(P31:P32) -> 0 | Q33: =SUM(Q31:Q32) -> 0 | R33: =SUM(R31:R32) -> 0 | S33: =SUM(S31:S32) -> 0 | T33: =SUM(T31:T32) -> 0 | ... BT33: =SUM(BT31:BT32) -> 11520000 | BV33: =SUMIF($M$3:$BT$3,BV$3,$M33:$BT33) -> 0 | BW33: =SUMIF($M$3:$BT$3,BW$3,$M33:$BT33) -> 9072000 | BX33: =SUMIF($M$3:$BT$3,BX$3,$M33:$BT33) -> 32616000 | BY33: =SUMIF($M$3:$BT$3,BY$3,$M33:$BT33) -> 53136000 | BZ33: =SUMIF($M$3:$BT$3,BZ$3,$M33:$BT33) -> 125280000
A35: Total Bookings | M35: =M29+M33 -> 240000 | N35: =N29+N33 -> 240000 | O35: =O29+O33 -> 240000 | P35: =P29+P33 -> 360000 | Q35: =Q29+Q33 -> 360000 | R35: =R29+R33 -> 360000 | S35: =S29+S33 -> 780000 | T35: =T29+T33 -> 780000 | ... BT35: =BT29+BT33 -> 24420000 | BV35: =SUMIF($M$3:$BT$3,BV$3,$M35:$BT35) -> 7560000 | BW35: =SUMIF($M$3:$BT$3,BW$3,$M35:$BT35) -> 36252000 | BX35: =SUMIF($M$3:$BT$3,BX$3,$M35:$BT35) -> 76896000 | BY35: =SUMIF($M$3:$BT$3,BY$3,$M35:$BT35) -> 157536000 | BZ35: =SUMIF($M$3:$BT$3,BZ$3,$M35:$BT35) -> 274680000
A36: Revenue
A37: Revenue (MRR) | M37: =SUM('Revenue Buildup'!$M35:M$35)/Assumptions!M9 -> 20000 | N37: =SUM('Revenue Buildup'!$M35:N$35)/Assumptions!N9 -> 40000 | O37: =SUM('Revenue Buildup'!$M35:O$35)/Assumptions!O9 -> 60000 | P37: =SUM('Revenue Buildup'!$M35:P$35)/Assumptions!P9 -> 90000 | Q37: =SUM('Revenue Buildup'!$M35:Q$35)/Assumptions!Q9 -> 120000 | R37: =SUM('Revenue Buildup'!$M35:R$35)/Assumptions!R9 -> 150000 | S37: =SUM('Revenue Buildup'!$M35:S$35)/Assumptions!S9 -> 215000 | T37: =SUM('Revenue Buildup'!$M35:T$35)/Assumptions!T9 -> 280000 | ... W37: =SUM('Revenue Buildup'!$M35:W$35)/Assumptions!W9 -> 535000 | X37: =SUM('Revenue Buildup'!M35:X35)/Assumptions!X9 -> 630000 | Y37: =SUM('Revenue Buildup'!N35:Y35)/Assumptions!Y9 -> 739000 | Z37: =SUM('Revenue Buildup'!O35:Z35)/Assumptions!Z9 -> 848000 | AA37: =SUM('Revenue Buildup'!P35:AA35)/Assumptions!AA9 -> 957000 | AB37: =SUM('Revenue Buildup'!Q35:AB35)/Assumptions!AB9 -> 1088000 | AC37: =SUM('Revenue Buildup'!R35:AC35)/Assumptions!AC9 -> 1219000 | AD37: =SUM('Revenue Buildup'!S35:AD35)/Assumptions!AD9 -> 1350000 | AE37: =SUM('Revenue Buildup'!T35:AE35)/Assumptions!AE9 -> 1613000 | ... BT37: =SUM('Revenue Buildup'!BI35:BT35)/Assumptions!BT9 -> 22890000 | BV37: =SUMIF($M$3:$BT$3,BV$3,$M37:$BT37) -> 2925000 | BW37: =SUMIF($M$3:$BT$3,BW$3,$M37:$BT37) -> 20010000 | BX37: =SUMIF($M$3:$BT$3,BX$3,$M37:$BT37) -> 58560000 | BY37: =SUMIF($M$3:$BT$3,BY$3,$M37:$BT37) -> 121647000 | BZ37: =SUMIF($M$3:$BT$3,BZ$3,$M37:$BT37) -> 220062000
A38: ARR | M38: =M37*12 -> 240000 | N38: =N37*12 -> 480000 | O38: =O37*12 -> 720000 | P38: =P37*12 -> 1080000 | Q38: =Q37*12 -> 1440000 | R38: =R37*12 -> 1800000 | S38: =S37*12 -> 2580000 | T38: =T37*12 -> 3360000 | ... BT38: =BT37*12 -> 274680000
A39: Type 1 & 2 SMBs
A40: New Clients | M40: =M7+M24 -> 8 | N40: =N7+N24 -> 8 | O40: =O7+O24 -> 8 | P40: =P7+P24 -> 12 | Q40: =Q7+Q24 -> 12 | R40: =R7+R24 -> 12 | S40: =S7+S24 -> 26 | T40: =T7+T24 -> 26 | ... BT40: =BT7+BT24 -> 315
A41: Existing Clients | M41: =M8+M25 -> 41 | N41: =M43 -> 49 | O41: =N43 -> 57 | P41: =O43 -> 65 | Q41: =P43 -> 77 | R41: =Q43 -> 89 | S41: =R43 -> 101 | T41: =S43 -> 127 | U41: =T43 -> 153 | ... BT41: =BS43 -> 8037
A42: Churned | Y42: =Y9+Y26 -> -1 | Z42: =Z9+Z26 -> -1 | AA42: =AA9+AA26 -> -1 | AB42: =AB9+AB26 -> -2 | AC42: =AC9+AC26 -> -2 | AD42: =AD9+AD26 -> -2 | AE42: =AE9+AE26 -> -4 | AF42: =AF9+AF26 -> -4 | ... BT42: =BT9+BT26 -> -25
...

Sheet Cost Buildup
A1: Cost Buildup
A2: Cells in Orange are assumptions | M2: MONTHLY | BV2: YEARLY
A3: Year | M3: 1 | N3: 1 | O3: 1 | P3: 1 | Q3: 1 | R3: 1 | S3: 1 | T3: 1 | U3: 1 | V3: 1 | W3: 1 | X3: 1 | Y3: =X3+1 -> 2 | Z3: =Y3 -> 2 | AA3: =Z3 -> 2 | AB3: =AA3 -> 2 | AC3: =AB3 -> 2 | AD3: =AC3 -> 2 | AE3: =AD3 -> 2 | AF3: =AE3 -> 2 | AG3: =AF3 -> 2 | ... AJ3: =AI3 -> 2 | AK3: 3 | AL3: 3 | AM3: 3 | AN3: 3 | AO3: 3 | AP3: 3 | AQ3: 3 | AR3: 3 | AS3: 3 | AT3: 3 | AU3: 3 | AV3: 3 | AW3: 4 | AX3: 4 | AY3: 4 | AZ3: 4 | BA3: 4 | BB3: 4 | BC3: 4 | BD3: 4 | BE3: 4 | BF3: 4 | BG3: 4 | BH3: 4 | BI3: 5 | BJ3: 5 | BK3: 5 | BL3: 5 | BM3: 5 | BN3: 5 | BO3: 5 | BP3: 5 | BQ3: 5 | BR3: 5 | BS3: 5 | BT3: 5 | BV3: 1 | BW3: 2 | BX3: 3 | BY3: 4 | BZ3: 5
A4: Months | M4: 1 | N4: =M4+1 -> 2 | O4: =N4+1 -> 3 | P4: =O4+1 -> 4 | Q4: =P4+1 -> 5 | R4: =Q4+1 -> 6 | S4: =R4+1 -> 7 | T4: =S4+1 -> 8 | U4: =T4+1 -> 9 | ... BT4: =BS4+1 -> 60 | BV4: 12 | BW4: 24 | BX4: 36 | BY4: 48 | BZ4: 60
A5: =Assumptions!A15 -> Direct Cost
A6: =Assumptions!A16 -> Hosting & Infrastructure Costs | M6: =SUM(M7:M9) -> 62580 | N6: =SUM(N7:N9) -> 71907.458 | O6: =SUM(O7:O9) -> 81234.915 | P6: =SUM(P7:P9) -> 90562.373 | Q6: =SUM(Q7:Q9) -> 99889.831 | R6: =SUM(R7:R9) -> 109217.29 | S6: =SUM(S7:S9) -> 118544.75 | T6: =SUM(T7:T9) -> 127872.2 | ... BT6: =SUM(BT7:BT9) -> 612900 | BV6: =SUMIF($M$3:$BT$3,BV$3,$M6:$BT6) -> 1366572.2 | BW6: =SUMIF($M$3:$BT$3,BW$3,$M6:$BT6) -> 2709726.1 | BX6: =SUMIF($M$3:$BT$3,BX$3,$M6:$BT6) -> 4052880 | BY6: =SUMIF($M$3:$BT$3,BY$3,$M6:$BT6) -> 5396033.9 | BZ6: =SUMIF($M$3:$BT$3,BZ$3,$M6:$BT6) -> 6739187.8
A7: =Assumptions!A17 -> Cloud services (AWS, Google Cloud, Azure) | M7: =Assumptions!M17 -> 50000 | N7: =Assumptions!N17 -> 57627.119 | O7: =Assumptions!O17 -> 65254.237 | P7: =Assumptions!P17 -> 72881.356 | Q7: =Assumptions!Q17 -> 80508.475 | R7: =Assumptions!R17 -> 88135.593 | S7: =Assumptions!S17 -> 95762.712 | T7: =Assumptions!T17 -> 103389.83 | ... BT7: =Assumptions!BT17 -> 500000 | BV7: =SUMIF($M$3:$BT$3,BV$3,$M7:$BT7) -> 1103389.8 | BW7: =SUMIF($M$3:$BT$3,BW$3,$M7:$BT7) -> 2201694.9 | BX7: =SUMIF($M$3:$BT$3,BX$3,$M7:$BT7) -> 3300000 | BY7: =SUMIF($M$3:$BT$3,BY$3,$M7:$BT7) -> 4398305.1 | BZ7: =SUMIF($M$3:$BT$3,BZ$3,$M7:$BT7) -> 5496610.2
A8: =Assumptions!A18 -> Database and storage (Amazon RDS, MongoDB Atlas) | M8: =Assumptions!M18 -> 10000 | N8: =Assumptions!N18 -> 11525.424 | O8: =Assumptions!O18 -> 13050.847 | P8: =Assumptions!P18 -> 14576.271 | Q8: =Assumptions!Q18 -> 16101.695 | R8: =Assumptions!R18 -> 17627.119 | S8: =Assumptions!S18 -> 19152.542 | T8: =Assumptions!T18 -> 20677.966 | ... BT8: =Assumptions!BT18 -> 100000 | BV8: =SUMIF($M$3:$BT$3,BV$3,$M8:$BT8) -> 220677.97 | BW8: =SUMIF($M$3:$BT$3,BW$3,$M8:$BT8) -> 440338.98 | BX8: =SUMIF($M$3:$BT$3,BX$3,$M8:$BT8) -> 660000 | BY8: =SUMIF($M$3:$BT$3,BY$3,$M8:$BT8) -> 879661.02 | BZ8: =SUMIF($M$3:$BT$3,BZ$3,$M8:$BT8) -> 1099322
A9: =Assumptions!A19 -> Content delivery networks (CDN) | M9: =Assumptions!M19 -> 2580 | N9: =Assumptions!N19 -> 2754.9153 | O9: =Assumptions!O19 -> 2929.8305 | P9: =Assumptions!P19 -> 3104.7458 | Q9: =Assumptions!Q19 -> 3279.661 | R9: =Assumptions!R19 -> 3454.5763 | S9: =Assumptions!S19 -> 3629.4915 | T9: =Assumptions!T19 -> 3804.4068 | ... BT9: =Assumptions!BT19 -> 12900 | BV9: =SUMIF($M$3:$BT$3,BV$3,$M9:$BT9) -> 42504.407 | BW9: =SUMIF($M$3:$BT$3,BW$3,$M9:$BT9) -> 67692.203 | BX9: =SUMIF($M$3:$BT$3,BX$3,$M9:$BT9) -> 92880 | BY9: =SUMIF($M$3:$BT$3,BY$3,$M9:$BT9) -> 118067.8 | BZ9: =SUMIF($M$3:$BT$3,BZ$3,$M9:$BT9) -> 143255.59
A10: =Assumptions!A20 -> Third-Party Software & API Costs | M10: =SUM(M11:M12) -> 12200 | N10: =SUM(N11:N12) -> 12538.983 | O10: =SUM(O11:O12) -> 12877.966 | P10: =SUM(P11:P12) -> 16816.949 | Q10: =SUM(Q11:Q12) -> 17155.932 | R10: =SUM(R11:R12) -> 17494.915 | S10: =SUM(S11:S12) -> 30433.898 | T10: =SUM(T11:T12) -> 30772.881 | ... BT10: =SUM(BT11:BT12) -> 330280 | BV10: =SUMIF($M$3:$BT$3,BV$3,$M10:$BT10) -> 309172.88 | BW10: =SUMIF($M$3:$BT$3,BW$3,$M10:$BT10) -> 1134506.4 | BX10: =SUMIF($M$3:$BT$3,BX$3,$M10:$BT10) -> 2188800 | BY10: =SUMIF($M$3:$BT$3,BY$3,$M10:$BT10) -> 3049773.6 | BZ10: =SUMIF($M$3:$BT$3,BZ$3,$M10:$BT10) -> 3794107.1
A11: =Assumptions!A21 -> Payment gateway fees (e.g., Stripe, Razorpay) | F11: =Assumptions!F21 -> as a % of bookings | M11: ='Revenue Buildup'!M18*Assumptions!M21 -> 7200 | N11: ='Revenue Buildup'!N18*Assumptions!N21 -> 7200 | O11: ='Revenue Buildup'!O18*Assumptions!O21 -> 7200 | P11: ='Revenue Buildup'!P18*Assumptions!P21 -> 10800 | Q11: ='Revenue Buildup'!Q18*Assumptions!Q21 -> 10800 | R11: ='Revenue Buildup'!R18*Assumptions!R21 -> 10800 | S11: ='Revenue Buildup'!S18*Assumptions!S21 -> 23400 | T11: ='Revenue Buildup'!T18*Assumptions!T21 -> 23400 | ... BT11: ='Revenue Buildup'!BT18*Assumptions!BT21 -> 305280 | BV11: =SUMIF($M$3:$BT$3,BV$3,$M11:$BT11) -> 226800 | BW11: =SUMIF($M$3:$BT$3,BW$3,$M11:$BT11) -> 1003320 | BX11: =SUMIF($M$3:$BT$3,BX$3,$M11:$BT11) -> 2008800 | BY11: =SUMIF($M$3:$BT$3,BY$3,$M11:$BT11) -> 2820960 | BZ11: =SUMIF($M$3:$BT$3,BZ$3,$M11:$BT11) -> 3516480
A12: =Assumptions!A22 -> Security services (e.g., Cloudflare, Auth0) | M12: =Assumptions!M22 -> 5000 | N12: =Assumptions!N22 -> 5338.9831 | O12: =Assumptions!O22 -> 5677.9661 | P12: =Assumptions!P22 -> 6016.9492 | Q12: =Assumptions!Q22 -> 6355.9322 | R12: =Assumptions!R22 -> 6694.9153 | S12: =Assumptions!S22 -> 7033.8983 | T12: =Assumptions!T22 -> 7372.8814 | ... BT12: =Assumptions!BT22 -> 25000 | BV12: =SUMIF($M$3:$BT$3,BV$3,$M12:$BT12) -> 82372.881 | BW12: =SUMIF($M$3:$BT$3,BW$3,$M12:$BT12) -> 131186.44 | BX12: =SUMIF($M$3:$BT$3,BX$3,$M12:$BT12) -> 180000 | BY12: =SUMIF($M$3:$BT$3,BY$3,$M12:$BT12) -> 228813.56 | BZ12: =SUMIF($M$3:$BT$3,BZ$3,$M12:$BT12) -> 277627.12
A13: =Assumptions!A23 -> Headcount
A14: =Assumptions!A24 -> Customer Support | C14: Base | F14: =Assumptions!F24 -> Account/Customer support | G14: =Assumptions!G24 -> 40 | H14: =Assumptions!H24 -> 40 | M14: =Assumptions!M24 -> 40 | N14: =Assumptions!N24 -> 40 | O14: =Assumptions!O24 -> 40 | P14: =Assumptions!P24 -> 40 | Q14: =Assumptions!Q24 -> 40 | R14: =Assumptions!R24 -> 40 | S14: =Assumptions!S24 -> 40 | T14: =Assumptions!T24 -> 40 | ... BT14: =Assumptions!BT24 -> 40
A15: Customer Support Headcount | M15: =ROUND('Revenue Buildup'!M10/Assumptions!M24,0) -> 1 | N15: =ROUND('Revenue Buildup'!N10/Assumptions!N24,0) -> 1 | O15: =ROUND('Revenue Buildup'!O10/Assumptions!O24,0) -> 1 | P15: =ROUND('Revenue Buildup'!P10/Assumptions!P24,0) -> 1 | Q15: =ROUND('Revenue Buildup'!Q10/Assumptions!Q24,0) -> 2 | R15: =ROUND('Revenue Buildup'!R10/Assumptions!R24,0) -> 2 | S15: =ROUND('Revenue Buildup'!S10/Assumptions!S24,0) -> 2 | T15: =ROUND('Revenue Buildup'!T10/Assumptions!T24,0) -> 2 | ... BT15: =ROUND('Revenue Buildup'!BT10/Assumptions!BT24,0) -> 70
A16: Customer Support Team Salary
A17: =Assumptions!A25 -> Customer Support | F17: =Assumptions!F25 -> Monthly Salary/Headcount | G17: =Assumptions!G25 -> 40000 | H17: 0.1 | I17: =Assumptions!I25 -> Annual Increment | M17: =(M15*$G$17)*(1+$H$17)^(M$3-1) -> 40000 | N17: =(N15*$G$17)*(1+$H$17)^(N$3-1) -> 40000 | O17: =(O15*$G$17)*(1+$H$17)^(O$3-1) -> 40000 | P17: =(P15*$G$17)*(1+$H$17)^(P$3-1) -> 40000 | Q17: =(Q15*$G$17)*(1+$H$17)^(Q$3-1) -> 80000 | R17: =(R15*$G$17)*(1+$H$17)^(R$3-1) -> 80000 | S17: =(S15*$G$17)*(1+$H$17)^(S$3-1) -> 80000 | T17: =(T15*$G$17)*(1+$H$17)^(T$3-1) -> 80000 | ... BT17: =(BT15*$G$17)*(1+$H$17)^(BT$3-1) -> 4099480 | BV17: =SUMIF($M$3:$BT$3,BV$3,$M17:$BT17) -> 1040000 | BW17: =SUMIF($M$3:$BT$3,BW$3,$M17:$BT17) -> 4664000 | BX17: =SUMIF($M$3:$BT$3,BX$3,$M17:$BT17) -> 13261600 | BY17: =SUMIF($M$3:$BT$3,BY$3,$M17:$BT17) -> 25022800 | BZ17: =SUMIF($M$3:$BT$3,BZ$3,$M17:$BT17) -> 41756132
A18: Total Direct Cost | M18: =SUM(M7:M9,M11:M12,M17) -> 114780 | N18: =SUM(N7:N9,N11:N12,N17) -> 124446.44 | O18: =SUM(O7:O9,O11:O12,O17) -> 134112.88 | P18: =SUM(P7:P9,P11:P12,P17) -> 147379.32 | Q18: =SUM(Q7:Q9,Q11:Q12,Q17) -> 197045.76 | R18: =SUM(R7:R9,R11:R12,R17) -> 206712.2 | S18: =SUM(S7:S9,S11:S12,S17) -> 228978.64 | T18: =SUM(T7:T9,T11:T12,T17) -> 238645.08 | ... BT18: =SUM(BT7:BT9,BT11:BT12,BT17) -> 5042660 | BV18: =SUMIF($M$3:$BT$3,BV$3,$M18:$BT18) -> 2715745.1 | BW18: =SUMIF($M$3:$BT$3,BW$3,$M18:$BT18) -> 8508232.5 | BX18: =SUMIF($M$3:$BT$3,BX$3,$M18:$BT18) -> 19503280 | BY18: =SUMIF($M$3:$BT$3,BY$3,$M18:$BT18) -> 33468607 | BZ18: =SUMIF($M$3:$BT$3,BZ$3,$M18:$BT18) -> 52289427
A19: =Assumptions!A26 -> Operating Expense
A20: =Assumptions!A27 -> Sales & Marketing Expense
A21: =Assumptions!A28 -> Sales Funnel
A22: =Assumptions!A29 -> Advetising/Marketing Expense Type 1 SMBs Focused | M22: =Assumptions!M29 -> 150000 | N22: =Assumptions!N29 -> 150000 | O22: =Assumptions!O29 -> 150000 | P22: =Assumptions!P29 -> 250000 | Q22: =Assumptions!Q29 -> 250000 | R22: =Assumptions!R29 -> 250000 | S22: =Assumptions!S29 -> 500000 | T22: =Assumptions!T29 -> 500000 | ... BT22: =Assumptions!BT29 -> 4000000 | BV22: =SUMIF($M$3:$BT$3,BV$3,$M22:$BT22) -> 4950000 | BW22: =SUMIF($M$3:$BT$3,BW$3,$M22:$BT22) -> 18150000 | BX22: =SUMIF($M$3:$BT$3,BX$3,$M22:$BT22) -> 29400000 | BY22: =SUMIF($M$3:$BT$3,BY$3,$M22:$BT22) -> 37800000 | BZ22: =SUMIF($M$3:$BT$3,BZ$3,$M22:$BT22) -> 46200000
A23: =Assumptions!A30 -> Advetising/Marketing Expense Type 2 SMBs Focused | M23: =Assumptions!M30 -> 75000 | N23: =Assumptions!N30 -> 75000 | O23: =Assumptions!O30 -> 75000 | P23: =Assumptions!P30 -> 125000 | Q23: =Assumptions!Q30 -> 125000 | R23: =Assumptions!R30 -> 125000 | S23: =Assumptions!S30 -> 250000 | T23: =Assumptions!T30 -> 250000 | ... BT23: =Assumptions!BT30 -> 4300000
A24: =Assumptions!A31 -> Cost/Lead Type 1 | G24: =Assumptions!G31 -> 2000 | H24: =Assumptions!H31 -> 2000 | M24: =Assumptions!M31 -> 2000 | N24: =Assumptions!N31 -> 2000 | O24: =Assumptions!O31 -> 2000 | P24: =Assumptions!P31 -> 2000 | Q24: =Assumptions!Q31 -> 2000 | R24: =Assumptions!R31 -> 2000 | S24: =Assumptions!S31 -> 2000 | T24: =Assumptions!T31 -> 2000 | ... BT24: =Assumptions!BT31 -> 2000
A25: =Assumptions!A32 -> Cost/Lead Type 2 | G25: =Assumptions!G32 -> 1000 | H25: =Assumptions!H32 -> 1000 | M25: =Assumptions!M32 -> 1000 | N25: =Assumptions!N32 -> 1000 | O25: =Assumptions!O32 -> 1000 | P25: =Assumptions!P32 -> 1000 | Q25: =Assumptions!Q32 -> 1000 | R25: =Assumptions!R32 -> 1000 | S25: =Assumptions!S32 -> 1000 | T25: =Assumptions!T32 -> 1000 | ... BT25: =Assumptions!BT32 -> 1000
A26: Leads | M26: =ROUND(M22/M24,0) -> 75 | N26: =ROUND(N22/N24,0) -> 75 | O26: =ROUND(O22/O24,0) -> 75 | P26: =ROUND(P22/P24,0) -> 125 | Q26: =ROUND(Q22/Q24,0) -> 125 | R26: =ROUND(R22/R24,0) -> 125 | S26: =ROUND(S22/S24,0) -> 250 | T26: =ROUND(T22/T24,0) -> 250 | ... BT26: =ROUND(BT22/BT24,0) -> 2000 | BV26: =SUMIF($M$3:$BT$3,BV$3,$M26:$BT26) -> 2475 | BW26: =SUMIF($M$3:$BT$3,BW$3,$M26:$BT26) -> 9075 | BX26: =SUMIF($M$3:$BT$3,BX$3,$M26:$BT26) -> 14700 | BY26: =SUMIF($M$3:$BT$3,BY$3,$M26:$BT26) -> 18900 | BZ26: =SUMIF($M$3:$BT$3,BZ$3,$M26:$BT26) -> 23100
A27: Leads | M27: =ROUND(M23/M25,0) -> 75 | N27: =ROUND(N23/N25,0) -> 75 | O27: =ROUND(O23/O25,0) -> 75 | P27: =ROUND(P23/P25,0) -> 125 | Q27: =ROUND(Q23/Q25,0) -> 125 | R27: =ROUND(R23/R25,0) -> 125 | S27: =ROUND(S23/S25,0) -> 250 | T27: =ROUND(T23/T25,0) -> 250 | ... BT27: =ROUND(BT23/BT25,0) -> 4300
A28: =Assumptions!A33 -> Sales Commission %
A29: =Assumptions!A34 -> New Bookings | M29: =Assumptions!M34*'Revenue Buildup'!M12 -> 48000 | N29: =Assumptions!N34*'Revenue Buildup'!N12 -> 48000 | O29: =Assumptions!O34*'Revenue Buildup'!O12 -> 48000 | P29: =Assumptions!P34*'Revenue Buildup'!P12 -> 72000 | Q29: =Assumptions!Q34*'Revenue Buildup'!Q12 -> 72000 | R29: =Assumptions!R34*'Revenue Buildup'!R12 -> 72000 | S29: =Assumptions!S34*'Revenue Buildup'!S12 -> 156000 | T29: =Assumptions!T34*'Revenue Buildup'!T12 -> 156000 | ... BT29: =Assumptions!BT34*'Revenue Buildup'!BT12 -> 1200000 | BV29: =SUMIF($M$3:$BT$3,BV$3,$M29:$BT29) -> 1512000 | BW29: =SUMIF($M$3:$BT$3,BW$3,$M29:$BT29) -> 5436000 | BX29: =SUMIF($M$3:$BT$3,BX$3,$M29:$BT29) -> 8856000 | BY29: =SUMIF($M$3:$BT$3,BY$3,$M29:$BT29) -> 11376000 | BZ29: =SUMIF($M$3:$BT$3,BZ$3,$M29:$BT29) -> 13896000
A30: =Assumptions!A35 -> Renewals | M30: =Assumptions!M35*'Revenue Buildup'!M14 -> 0 | N30: =Assumptions!N35*'Revenue Buildup'!N14 -> 0 | O30: =Assumptions!O35*'Revenue Buildup'!O14 -> 0 | P30: =Assumptions!P35*'Revenue Buildup'!P14 -> 0 | Q30: =Assumptions!Q35*'Revenue Buildup'!Q14 -> 0 | R30: =Assumptions!R35*'Revenue Buildup'!R14 -> 0 | S30: =Assumptions!S35*'Revenue Buildup'!S14 -> 0 | T30: =Assumptions!T35*'Revenue Buildup'!T14 -> 0 | ... BT30: =Assumptions!BT35*'Revenue Buildup'!BT14 -> 174000 | BV30: =SUMIF($M$3:$BT$3,BV$3,$M30:$BT30) -> 0 | BW30: =SUMIF($M$3:$BT$3,BW$3,$M30:$BT30) -> 261000 | BX30: =SUMIF($M$3:$BT$3,BX$3,$M30:$BT30) -> 945000 | BY30: =SUMIF($M$3:$BT$3,BY$3,$M30:$BT30) -> 1548000 | BZ30: =SUMIF($M$3:$BT$3,BZ$3,$M30:$BT30) -> 1989000
A31: =Assumptions!A36 -> Expansion | M31: =Assumptions!M36*'Revenue Buildup'!M15 -> 0 | N31: =Assumptions!N36*'Revenue Buildup'!N15 -> 0 | O31: =Assumptions!O36*'Revenue Buildup'!O15 -> 0 | P31: =Assumptions!P36*'Revenue Buildup'!P15 -> 0 | Q31: =Assumptions!Q36*'Revenue Buildup'!Q15 -> 0 | R31: =Assumptions!R36*'Revenue Buildup'!R15 -> 0 | S31: =Assumptions!S36*'Revenue Buildup'!S15 -> 0 | T31: =Assumptions!T36*'Revenue Buildup'!T15 -> 0 | ... BT31: =Assumptions!BT36*'Revenue Buildup'!BT15 -> 69600 | BV31: =SUMIF($M$3:$BT$3,BV$3,$M31:$BT31) -> 0 | BW31: =SUMIF($M$3:$BT$3,BW$3,$M31:$BT31) -> 104400 | BX31: =SUMIF($M$3:$BT$3,BX$3,$M31:$BT31) -> 378000 | BY31: =SUMIF($M$3:$BT$3,BY$3,$M31:$BT31) -> 619200 | BZ31: =SUMIF($M$3:$BT$3,BZ$3,$M31:$BT31) -> 795600
A32: Total Commissions | M32: =SUM(M29:M31) -> 48000 | N32: =SUM(N29:N31) -> 48000 | O32: =SUM(O29:O31) -> 48000 | P32: =SUM(P29:P31) -> 72000 | Q32: =SUM(Q29:Q31) -> 72000 | R32: =SUM(R29:R31) -> 72000 | S32: =SUM(S29:S31) -> 156000 | T32: =SUM(T29:T31) -> 156000 | ... BT32: =SUM(BT29:BT31) -> 1443600
A33: =Assumptions!A37 -> Headcount
A34: =Assumptions!A38 -> Sales (SDR) | C34: Base | F34: =Assumptions!F38 -> Leads/Sales Agent/Month | G34: =Assumptions!G38 -> 50 | H34: =Assumptions!H38 -> 50 | M34: =Assumptions!M38 -> 50 | N34: =Assumptions!N38 -> 50 | O34: =Assumptions!O38 -> 50 | P34: =Assumptions!P38 -> 50 | Q34: =Assumptions!Q38 -> 50 | R34: =Assumptions!R38 -> 50 | S34: =Assumptions!S38 -> 50 | T34: =Assumptions!T38 -> 50 | ... BT34: =Assumptions!BT38 -> 50
A35: =Assumptions!A39 -> Sales Manager | C35: Base | F35: =Assumptions!F39 -> Sales Agents/Sales Manager | G35: =Assumptions!G39 -> 10 | H35: =Assumptions!H39 -> 10 | M35: =Assumptions!M39 -> 10 | N35: =Assumptions!N39 -> 10 | O35: =Assumptions!O39 -> 10 | P35: =Assumptions!P39 -> 10 | Q35: =Assumptions!Q39 -> 10 | R35: =Assumptions!R39 -> 10 | S35: =Assumptions!S39 -> 10 | T35: =Assumptions!T39 -> 10 | ... BT35: =Assumptions!BT39 -> 10
A36: Sales (SDR) Headcount | M36: =ROUND(M26/M34,0) -> 2 | N36: =ROUND(N26/N34,0) -> 2 | O36: =ROUND(O26/O34,0) -> 2 | P36: =ROUND(P26/P34,0) -> 3 | Q36: =ROUND(Q26/Q34,0) -> 3 | R36: =ROUND(R26/R34,0) -> 3 | S36: =ROUND(S26/S34,0) -> 5 | T36: =ROUND(T26/T34,0) -> 5 | ... BT36: =ROUND(BT26/BT34,0) -> 40
A37: Sales Manager Headcount | M37: =ROUND(M36/M35,0) -> 0 | N37: =ROUND(N36/N35,0) -> 0 | O37: =ROUND(O36/O35,0) -> 0 | P37: =ROUND(P36/P35,0) -> 0 | Q37: =ROUND(Q36/Q35,0) -> 0 | R37: =ROUND(R36/R35,0) -> 0 | S37: =ROUND(S36/S35,0) -> 1 | T37: =ROUND(T36/T35,0) -> 1 | ... BT37: =ROUND(BT36/BT35,0) -> 4
A38: =Assumptions!A40 -> Sales Team Salary
A39: =Assumptions!A41 -> Sales (SDR) | F39: =Assumptions!F41 -> Monthly Salary/Headcount | G39: =Assumptions!G41 -> 50000 | H39: =Assumptions!H41 -> 0.15 | I39: =Assumptions!I41 -> Annual Increment | M39: =($G39*M36)*(1+$H39)^(M$3-1) -> 100000 | N39: =($G39*N36)*(1+$H39)^(N$3-1) -> 100000 | O39: =($G39*O36)*(1+$H39)^(O$3-1) -> 100000 | P39: =($G39*P36)*(1+$H39)^(P$3-1) -> 150000 | Q39: =($G39*Q36)*(1+$H39)^(Q$3-1) -> 150000 | R39: =($G39*R36)*(1+$H39)^(R$3-1) -> 150000 | S39: =($G39*S36)*(1+$H39)^(S$3-1) -> 250000 | T39: =($G39*T36)*(1+$H39)^(T$3-1) -> 250000 | ... BT39: =($G39*BT36)*(1+$H39)^(BT$3-1) -> 3498012.5 | BV39: =SUMIF($M$3:$BT$3,BV$3,$M39:$BT39) -> 2700000 | BW39: =SUMIF($M$3:$BT$3,BW$3,$M39:$BT39) -> 10522500 | BX39: =SUMIF($M$3:$BT$3,BX$3,$M39:$BT39) -> 19440750 | BY39: =SUMIF($M$3:$BT$3,BY$3,$M39:$BT39) -> 28744537 | BZ39: =SUMIF($M$3:$BT$3,BZ$3,$M39:$BT39) -> 40402044
A40: =Assumptions!A42 -> Sales Manager | F40: =Assumptions!F42 -> Monthly Salary/Headcount | G40: 70000 | H40: =Assumptions!H42 -> 0.15 | I40: =Assumptions!I42 -> Annual Increment | M40: =($G40*M37)*(1+$H40)^(M$3-1) -> 0 | N40: =($G40*N37)*(1+$H40)^(N$3-1) -> 0 | O40: =($G40*O37)*(1+$H40)^(O$3-1) -> 0 | P40: =($G40*P37)*(1+$H40)^(P$3-1) -> 0 | Q40: =($G40*Q37)*(1+$H40)^(Q$3-1) -> 0 | R40: =($G40*R37)*(1+$H40)^(R$3-1) -> 0 | S40: =($G40*S37)*(1+$H40)^(S$3-1) -> 70000 | T40: =($G40*T37)*(1+$H40)^(T$3-1) -> 70000 | ... BT40: =($G40*BT37)*(1+$H40)^(BT$3-1) -> 489721.75 | BV40: =SUMIF($M$3:$BT$3,BV$3,$M40:$BT40) -> 420000 | BW40: =SUMIF($M$3:$BT$3,BW$3,$M40:$BT40) -> 1449000 | BX40: =SUMIF($M$3:$BT$3,BX$3,$M40:$BT40) -> 2777250 | BY40: =SUMIF($M$3:$BT$3,BY$3,$M40:$BT40) -> 3832605 | BZ40: =SUMIF($M$3:$BT$3,BZ$3,$M40:$BT40) -> 5876661
...

Sheet FAS
A1: Fixed Asset Schedule
A2: Cells in Orange are assumptions | M2: MONTHLY | BV2: YEARLY
A3: Year | M3: 1 | N3: 1 | O3: 1 | P3: 1 | Q3: 1 | R3: 1 | S3: 1 | T3: 1 | U3: 1 | V3: 1 | W3: 1 | X3: 1 | Y3: =X3+1 -> 2 | Z3: =Y3 -> 2 | AA3: =Z3 -> 2 | AB3: =AA3 -> 2 | AC3: =AB3 -> 2 | AD3: =AC3 -> 2 | AE3: =AD3 -> 2 | AF3: =AE3 -> 2 | AG3: =AF3 -> 2 | ... AJ3: =AI3 -> 2 | AK3: 3 | AL3: 3 | AM3: 3 | AN3: 3 | AO3: 3 | AP3: 3 | AQ3: 3 | AR3: 3 | AS3: 3 | AT3: 3 | AU3: 3 | AV3: 3 | AW3: 4 | AX3: 4 | AY3: 4 | AZ3: 4 | BA3: 4 | BB3: 4 | BC3: 4 | BD3: 4 | BE3: 4 | BF3: 4 | BG3: 4 | BH3: 4 | BI3: 5 | BJ3: 5 | BK3: 5 | BL3: 5 | BM3: 5 | BN3: 5 | BO3: 5 | BP3: 5 | BQ3: 5 | BR3: 5 | BS3: 5 | BT3: 5 | BV3: 1 | BW3: 2 | BX3: 3 | BY3: 4 | BZ3: 5
A4: Months | M4: 1 | N4: =M4+1 -> 2 | O4: =N4+1 -> 3 | P4: =O4+1 -> 4 | Q4: =P4+1 -> 5 | R4: =Q4+1 -> 6 | S4: =R4+1 -> 7 | T4: =S4+1 -> 8 | U4: =T4+1 -> 9 | ... BT4: =BS4+1 -> 60 | BV4: 12 | BW4: 24 | BX4: 36 | BY4: 48 | BZ4: 60

Sheet IS
A1: Income Statement
A2: Cells in Orange are assumptions | M2: MONTHLY | BV2: YEARLY | CB2: Commonsize Statement
A3: Year | M3: 1 | N3: 1 | O3: 1 | P3: 1 | Q3: 1 | R3: 1 | S3: 1 | T3: 1 | U3: 1 | V3: 1 | W3: 1 | X3: 1 | Y3: =X3+1 -> 2 | Z3: =Y3 -> 2 | AA3: =Z3 -> 2 | AB3: =AA3 -> 2 | AC3: =AB3 -> 2 | AD3: =AC3 -> 2 | AE3: =AD3 -> 2 | AF3: =AE3 -> 2 | AG3: =AF3 -> 2 | ... AJ3: =AI3 -> 2 | AK3: 3 | AL3: 3 | AM3: 3 | AN3: 3 | AO3: 3 | AP3: 3 | AQ3: 3 | AR3: 3 | AS3: 3 | AT3: 3 | AU3: 3 | AV3: 3 | AW3: 4 | AX3: 4 | AY3: 4 | AZ3: 4 | BA3: 4 | BB3: 4 | BC3: 4 | BD3: 4 | BE3: 4 | BF3: 4 | BG3: 4 | BH3: 4 | BI3: 5 | BJ3: 5 | BK3: 5 | BL3: 5 | BM3: 5 | BN3: 5 | BO3: 5 | BP3: 5 | BQ3: 5 | BR3: 5 | BS3: 5 | BT3: 5 | BV3: 1 | BW3: 2 | BX3: 3 | BY3: 4 | BZ3: 5 | CB3: 1 | CC3: 2 | CD3: 3 | CE3: 4 | CF3: 5
A4: Months | M4: 1 | N4: =M4+1 -> 2 | O4: =N4+1 -> 3 | P4: =O4+1 -> 4 | Q4: =P4+1 -> 5 | R4: =Q4+1 -> 6 | S4: =R4+1 -> 7 | T4: =S4+1 -> 8 | U4: =T4+1 -> 9 | ... BT4: =BS4+1 -> 60 | BV4: 12 | BW4: 24 | BX4: 36 | BY4: 48 | BZ4: 60 | CB4: 12 | CC4: 24 | CD4: 36 | CE4: 48 | CF4: 60
A5: Revenues
B6: Bookings | M6: ='Revenue Buildup'!M18 -> 480000 | N6: ='Revenue Buildup'!N18 -> 480000 | O6: ='Revenue Buildup'!O18 -> 480000 | P6: ='Revenue Buildup'!P18 -> 720000 | Q6: ='Revenue Buildup'!Q18 -> 720000 | R6: ='Revenue Buildup'!R18 -> 720000 | S6: ='Revenue Buildup'!S18 -> 1560000 | T6: ='Revenue Buildup'!T18 -> 1560000 | ... BT6: ='Revenue Buildup'!BT18 -> 20352000 | BV6: =SUMIF($M$3:$BT$3,BV$3,$M6:$BT6) -> 15120000 | BW6: =SUMIF($M$3:$BT$3,BW$3,$M6:$BT6) -> 66888000 | BX6: =SUMIF($M$3:$BT$3,BX$3,$M6:$BT6) -> 133920000 | BY6: =SUMIF($M$3:$BT$3,BY$3,$M6:$BT6) -> 188064000 | BZ6: =SUMIF($M$3:$BT$3,BZ$3,$M6:$BT6) -> 234432000
A7: [+] | B7: Revenue | M7: ='Revenue Buildup'!M20 -> 40000 | N7: ='Revenue Buildup'!N20 -> 80000 | O7: ='Revenue Buildup'!O20 -> 120000 | P7: ='Revenue Buildup'!P20 -> 180000 | Q7: ='Revenue Buildup'!Q20 -> 240000 | R7: ='Revenue Buildup'!R20 -> 300000 | S7: ='Revenue Buildup'!S20 -> 430000 | T7: ='Revenue Buildup'!T20 -> 560000 | ... BT7: ='Revenue Buildup'!BT20 -> 19536000 | BV7: =SUMIF($M$3:$BT$3,BV$3,$M7:$BT7) -> 5850000 | BW7: =SUMIF($M$3:$BT$3,BW$3,$M7:$BT7) -> 37896000 | BX7: =SUMIF($M$3:$BT$3,BX$3,$M7:$BT7) -> 105024000 | BY7: =SUMIF($M$3:$BT$3,BY$3,$M7:$BT7) -> 167100000 | BZ7: =SUMIF($M$3:$BT$3,BZ$3,$M7:$BT7) -> 213000000 | CB7: =BV7/BV$7 -> 1 | CC7: =BW7/BW$7 -> 1 | CD7: =BX7/BX$7 -> 1 | CE7: =BY7/BY$7 -> 1 | CF7: =BZ7/BZ$7 -> 1
A8: Direct Expenses | BW8: =BW7/BV7-1 -> 5.4779487 | BX8: =BX7/BW7-1 -> 1.7713743 | BY8: =BY7/BX7-1 -> 0.5910649 | BZ8: =BZ7/BY7-1 -> 0.27468582
A9: [-] | B9: ='Cost Buildup'!A6 -> Hosting & Infrastructure Costs | M9: ='Cost Buildup'!M6 -> 62580 | N9: ='Cost Buildup'!N6 -> 71907.458 | O9: ='Cost Buildup'!O6 -> 81234.915 | P9: ='Cost Buildup'!P6 -> 90562.373 | Q9: ='Cost Buildup'!Q6 -> 99889.831 | R9: ='Cost Buildup'!R6 -> 109217.29 | S9: ='Cost Buildup'!S6 -> 118544.75 | T9: ='Cost Buildup'!T6 -> 127872.2 | ... BT9: ='Cost Buildup'!BT6 -> 612900 | BV9: =SUMIF($M$3:$BT$3,BV$3,$M9:$BT9) -> 1366572.2 | BW9: =SUMIF($M$3:$BT$3,BW$3,$M9:$BT9) -> 2709726.1 | BX9: =SUMIF($M$3:$BT$3,BX$3,$M9:$BT9) -> 4052880 | BY9: =SUMIF($M$3:$BT$3,BY$3,$M9:$BT9) -> 5396033.9 | BZ9: =SUMIF($M$3:$BT$3,BZ$3,$M9:$BT9) -> 6739187.8 | CB9: =BV9/BV$7 -> 0.23360209 | CC9: =BW9/BW$7 -> 0.071504278 | CD9: =BX9/BX$7 -> 0.038590037 | CE9: =BY9/BY$7 -> 0.032292244 | CF9: =BZ9/BZ$7 -> 0.031639379
A10: [-] | B10: ='Cost Buildup'!A10 -> Third-Party Software & API Costs | M10: ='Cost Buildup'!M10 -> 12200 | N10: ='Cost Buildup'!N10 -> 12538.983 | O10: ='Cost Buildup'!O10 -> 12877.966 | P10: ='Cost Buildup'!P10 -> 16816.949 | Q10: ='Cost Buildup'!Q10 -> 17155.932 | R10: ='Cost Buildup'!R10 -> 17494.915 | S10: ='Cost Buildup'!S10 -> 30433.898 | T10: ='Cost Buildup'!T10 -> 30772.881 | ... BT10: ='Cost Buildup'!BT10 -> 330280 | BV10: =SUMIF($M$3:$BT$3,BV$3,$M10:$BT10) -> 309172.88 | BW10: =SUMIF($M$3:$BT$3,BW$3,$M10:$BT10) -> 1134506.4 | BX10: =SUMIF($M$3:$BT$3,BX$3,$M10:$BT10) -> 2188800 | BY10: =SUMIF($M$3:$BT$3,BY$3,$M10:$BT10) -> 3049773.6 | BZ10: =SUMIF($M$3:$BT$3,BZ$3,$M10:$BT10) -> 3794107.1 | CB10: =BV10/BV$7 -> 0.052850065 | CC10: =BW10/BW$7 -> 0.029937366 | CD10: =BX10/BX$7 -> 0.020840951 | CE10: =BY10/BY$7 -> 0.018251188 | CF10: =BZ10/BZ$7 -> 0.017812709
A11: [-] | B11: ='Cost Buildup'!A17 -> Customer Support | M11: ='Cost Buildup'!M17 -> 40000 | N11: ='Cost Buildup'!N17 -> 40000 | O11: ='Cost Buildup'!O17 -> 40000 | P11: ='Cost Buildup'!P17 -> 40000 | Q11: ='Cost Buildup'!Q17 -> 80000 | R11: ='Cost Buildup'!R17 -> 80000 | S11: ='Cost Buildup'!S17 -> 80000 | T11: ='Cost Buildup'!T17 -> 80000 | ... BT11: ='Cost Buildup'!BT17 -> 4099480 | BV11: =SUMIF($M$3:$BT$3,BV$3,$M11:$BT11) -> 1040000 | BW11: =SUMIF($M$3:$BT$3,BW$3,$M11:$BT11) -> 4664000 | BX11: =SUMIF($M$3:$BT$3,BX$3,$M11:$BT11) -> 13261600 | BY11: =SUMIF($M$3:$BT$3,BY$3,$M11:$BT11) -> 25022800 | BZ11: =SUMIF($M$3:$BT$3,BZ$3,$M11:$BT11) -> 41756132 | CB11: =BV11/BV$7 -> 0.17777778 | CC11: =BW11/BW$7 -> 0.12307368 | CD11: =BX11/BX$7 -> 0.12627209 | CE11: =BY11/BY$7 -> 0.14974746 | CF11: =BZ11/BZ$7 -> 0.19603818
A12: COGS | M12: =SUM(M9:M11) -> 114780 | N12: =SUM(N9:N11) -> 124446.44 | O12: =SUM(O9:O11) -> 134112.88 | P12: =SUM(P9:P11) -> 147379.32 | Q12: =SUM(Q9:Q11) -> 197045.76 | R12: =SUM(R9:R11) -> 206712.2 | S12: =SUM(S9:S11) -> 228978.64 | T12: =SUM(T9:T11) -> 238645.08 | ... BT12: =SUM(BT9:BT11) -> 5042660 | BV12: =SUMIF($M$3:$BT$3,BV$3,$M12:$BT12) -> 2715745.1 | BW12: =SUMIF($M$3:$BT$3,BW$3,$M12:$BT12) -> 8508232.5 | BX12: =SUMIF($M$3:$BT$3,BX$3,$M12:$BT12) -> 19503280 | BY12: =SUMIF($M$3:$BT$3,BY$3,$M12:$BT12) -> 33468607 | BZ12: =SUMIF($M$3:$BT$3,BZ$3,$M12:$BT12) -> 52289427 | CB12: =BV12/BV$7 -> 0.46422993 | CC12: =BW12/BW$7 -> 0.22451532 | CD12: =BX12/BX$7 -> 0.18570308 | CE12: =BY12/BY$7 -> 0.20029089 | CF12: =BZ12/BZ$7 -> 0.24549027
B13: Gross Profit | M13: =M7-M12 -> -74780 | N13: =N7-N12 -> -44446.441 | O13: =O7-O12 -> -14112.881 | P13: =P7-P12 -> 32620.678 | Q13: =Q7-Q12 -> 42954.237 | R13: =R7-R12 -> 93287.797 | S13: =S7-S12 -> 201021.36 | T13: =T7-T12 -> 321354.92 | ... BT13: =BT7-BT12 -> 14493340 | BV13: =BV7-BV12 -> 3134254.9 | BW13: =BW7-BW12 -> 29387767 | BX13: =BX7-BX12 -> 85520720 | BY13: =BY7-BY12 -> 1.3363139e+08 | BZ13: =BZ7-BZ12 -> 1.6071057e+08 | CB13: =BV13/BV$7 -> 0.53577007 | CC13: =BW13/BW$7 -> 0.77548468 | CD13: =BX13/BX$7 -> 0.81429692 | CE13: =BY13/BY$7 -> 0.79970911 | CF13: =BZ13/BZ$7 -> 0.75450973
B14: Gross Profit % | M14: =M13/M$7 -> -1.8695 | N14: =N13/N$7 -> -0.55558051 | O14: =O13/O$7 -> -0.11760734 | P14: =P13/P$7 -> 0.18122599 | Q14: =Q13/Q$7 -> 0.17897599 | R14: =R13/R$7 -> 0.31095932 | S14: =S13/S$7 -> 0.46749153 | T14: =T13/T$7 -> 0.57384806 | ... BT14: =BT13/BT$7 -> 0.74187858 | BV14: =BV13/BV$7 -> 0.53577007 | BW14: =BW13/BW$7 -> 0.77548468 | BX14: =BX13/BX$7 -> 0.81429692 | BY14: =BY13/BY$7 -> 0.79970911 | BZ14: =BZ13/BZ$7 -> 0.75450973
A15: Operating Expenses
A16: [+] | B16: Sales & Marketing | M16: ='Cost Buildup'!M22+'Cost Buildup'!M32 -> 198000 | N16: ='Cost Buildup'!N22+'Cost Buildup'!N32 -> 198000 | O16: ='Cost Buildup'!O22+'Cost Buildup'!O32 -> 198000 | P16: ='Cost Buildup'!P22+'Cost Buildup'!P32 -> 322000 | Q16: ='Cost Buildup'!Q22+'Cost Buildup'!Q32 -> 322000 | R16: ='Cost Buildup'!R22+'Cost Buildup'!R32 -> 322000 | S16: ='Cost Buildup'!S22+'Cost Buildup'!S32 -> 656000 | T16: ='Cost Buildup'!T22+'Cost Buildup'!T32 -> 656000 | ... BT16: ='Cost Buildup'!BT22+'Cost Buildup'!BT32 -> 5443600 | BV16: =SUMIF($M$3:$BT$3,BV$3,$M16:$BT16) -> 6462000 | BW16: =SUMIF($M$3:$BT$3,BW$3,$M16:$BT16) -> 23951400 | BX16: =SUMIF($M$3:$BT$3,BX$3,$M16:$BT16) -> 39579000 | BY16: =SUMIF($M$3:$BT$3,BY$3,$M16:$BT16) -> 51343200 | BZ16: =SUMIF($M$3:$BT$3,BZ$3,$M16:$BT16) -> 62880600 | CB16: =BV16/BV$7 -> 1.1046154 | CC16: =BW16/BW$7 -> 0.63202977 | CD16: =BX16/BX$7 -> 0.37685672 | CE16: =BY16/BY$7 -> 0.30726032 | CF16: =BZ16/BZ$7 -> 0.29521408
A17: [+] | B17: G&A | M17: =SUM('Cost Buildup'!M52:M53) -> 90000 | N17: =SUM('Cost Buildup'!N52:N53) -> 90515.937 | O17: =SUM('Cost Buildup'!O52:O53) -> 91031.875 | P17: =SUM('Cost Buildup'!P52:P53) -> 100702.59 | Q17: =SUM('Cost Buildup'!Q52:Q53) -> 110476.5 | R17: =SUM('Cost Buildup'!R52:R53) -> 111095.62 | S17: =SUM('Cost Buildup'!S52:S53) -> 148953 | T17: =SUM('Cost Buildup'!T52:T53) -> 149778.5 | ... BT17: =SUM('Cost Buildup'!BT52:BT53) -> 1674120.2 | BV17: =SUMIF($M$3:$BT$3,BV$3,$M17:$BT17) -> 1642610.5 | BW17: =SUMIF($M$3:$BT$3,BW$3,$M17:$BT17) -> 4785088.6 | BX17: =SUMIF($M$3:$BT$3,BX$3,$M17:$BT17) -> 9461306.8 | BY17: =SUMIF($M$3:$BT$3,BY$3,$M17:$BT17) -> 13204885 | BZ17: =SUMIF($M$3:$BT$3,BZ$3,$M17:$BT17) -> 17927058 | CB17: =BV17/BV$7 -> 0.28078812 | CC17: =BW17/BW$7 -> 0.12626896 | CD17: =BX17/BX$7 -> 0.090087093 | CE17: =BY17/BY$7 -> 0.079023849 | CF17: =BZ17/BZ$7 -> 0.08416459
